Workbook

Sheet Лист1
B1: 5 | C1: 5.1 | D1: 5.2 | E1: 5.3 | F1: 5.4 | G1: 5.5 | H1: 5.6 | I1: 5.7 | J1: 5.8 | K1: 5.9 | N1: 5 | O1: 5.1 | P1: 5.2 | Q1: 5.3 | R1: 5.4 | S1: 5.5 | T1: 5.6 | U1: 5.7 | V1: 5.8 | W1: 5.9
A2: 10 | B2: 1.58 | C2: 0.84 | D2: 1.2 | E2: 1.21 | F2: 1.22 | G2: 1.22 | H2: 1.23 | I2: 1.23 | J2: 1.49 | K2: 1.66 | M2: 10 | N2: 1.58 | O2: 0.84 | P2: 1.2 | Q2: 1.21 | R2: 1.22 | S2: 1.22 | T2: 1.23 | U2: 1.23 | V2: 1.49 | W2: 1.66 | AA2: =MIN(AA3,AB2,N2) -> 0.84 | AB2: =MIN(AB3,AC2,O2) -> 0.84 | AC2: =MIN(AC3,AD2,P2) -> 1.2 | AD2: =MIN(AD3,AE2,Q2) -> 1.21 | AE2: =MIN(AE3,AF2,R2) -> 1.22 | AF2: =MIN(AF3,AG2,S2) -> 1.22 | AG2: =MIN(AG3,AH2,T2) -> 1.23 | AH2: =MIN(AH3,AI2,U2) -> 1.23 | AI2: =MIN(AI3,AJ2,V2) -> 1.49 | AJ2: =MIN(AJ3,W2) -> 1.66
A3: 14 | B3: 1.67 | C3: 1.67 | D3: 1.67 | E3: 1.81 | F3: 1.95 | G3: 2.06 | H3: 2.15 | I3: 2.23 | J3: 2.3 | K3: 2.36 | M3: 14 | N3: 1.67 | O3: 1.67 | P3: 1.67 | Q3: 1.81 | R3: 1.95 | S3: 2.06 | T3: 2.15 | U3: 2.23 | V3: 2.3 | W3: 2.36 | AA3: =MIN(AA4,AB3,N3) -> 1.67 | AB3: =MIN(AB4,AC3,O3) -> 1.67 | AC3: =MIN(AC4,AD3,P3) -> 1.67 | AD3: =MIN(AD4,AE3,Q3) -> 1.79 | AE3: =MIN(AE4,AF3,R3) -> 1.85 | AF3: =MIN(AF4,AG3,S3) -> 2.05 | AG3: =MIN(AG4,AH3,T3) -> 2.15 | AH3: =MIN(AH4,AI3,U3) -> 2.17 | AI3: =MIN(AI4,AJ3,V3) -> 2.3 | AJ3: =MIN(AJ4,W3) -> 2.36
A4: 18 | B4: 2.28 | C4: 2.97 | D4: 2.28 | E4: 3.07 | F4: 2.28 | G4: 3 | H4: 3.12 | I4: 2.17 | J4: 2.9 | K4: 2.47 | M4: 18 | N4: 2.28 | O4: 2.97 | P4: 2.28 | Q4: 3.07 | R4: 2.28 | S4: 3 | T4: 3.12 | U4: 2.17 | V4: 2.9 | W4: 2.47 | AA4: =MIN(AA5,AB4,N4) -> 1.79 | AB4: =MIN(AB5,AC4,O4) -> 1.79 | AC4: =MIN(AC5,AD4,P4) -> 1.79 | AD4: =MIN(AD5,AE4,Q4) -> 1.79 | AE4: =MIN(AE5,AF4,R4) -> 1.85 | AF4: =MIN(AF5,AG4,S4) -> 2.05 | AG4: =MIN(AG5,AH4,T4) -> 2.17 | AH4: =MIN(AH5,AI4,U4) -> 2.17 | AI4: =MIN(AI5,AJ4,V4) -> 2.31 | AJ4: =MIN(AJ5,W4) -> 2.43
A5: 22 | B5: 3.11 | C5: 3.86 | D5: 3.74 | E5: 3.81 | F5: 3.75 | G5: 3.03 | H5: 3.85 | I5: 3.77 | J5: 4.2 | K5: 3.03 | M5: 22 | N5: 3.11 | O5: 3.86 | P5: 3.74 | Q5: 3.81 | R5: 3.75 | S5: 3.03 | T5: 3.85 | U5: 3.77 | V5: 4.2 | W5: 3.03 | AA5: =MIN(AA6,AB5,N5) -> 1.79 | AB5: =MIN(AB6,AC5,O5) -> 1.79 | AC5: =MIN(AC6,AD5,P5) -> 1.79 | AD5: =MIN(AD6,AE5,Q5) -> 1.79 | AE5: =MIN(AE6,AF5,R5) -> 1.85 | AF5: =MIN(AF6,AG5,S5) -> 2.05 | AG5: =MIN(AG6,AH5,T5) -> 2.17 | AH5: =MIN(AH6,AI5,U5) -> 2.17 | AI5: =MIN(AI6,AJ5,V5) -> 2.31 | AJ5: =MIN(AJ6,W5) -> 2.43
A6: 26 | B6: 4.74 | C6: 3.88 | D6: 4.72 | E6: 4.43 | F6: 3.83 | G6: 3.96 | H6: 4.82 | I6: 3.83 | J6: 4.24 | K6: 3.83 | M6: 26 | N6: 4.74 | O6: 3.88 | P6: 4.72 | Q6: 4.43 | R6: 3.83 | S6: 3.96 | T6: 4.82 | U6: 3.83 | V6: 4.24 | W6: 3.83 | AA6: =MIN(AA7,AB6,N6) -> 1.79 | AB6: =MIN(AB7,AC6,O6) -> 1.79 | AC6: =MIN(AC7,AD6,P6) -> 1.79 | AD6: =MIN(AD7,AE6,Q6) -> 1.79 | AE6: =MIN(AE7,AF6,R6) -> 1.85 | AF6: =MIN(AF7,AG6,S6) -> 2.05 | AG6: =MIN(AG7,AH6,T6) -> 2.17 | AH6: =MIN(AH7,AI6,U6) -> 2.17 | AI6: =MIN(AI7,AJ6,V6) -> 2.31 | AJ6: =MIN(AJ7,W6) -> 2.43
A7: 30 | B7: 2.35 | C7: 2.36 | D7: 1.92 | E7: 1.79 | F7: 1.85 | G7: 2.05 | H7: 2.17 | I7: 2.26 | J7: 2.35 | K7: 2.43 | M7: 30 | N7: 2.35 | O7: 2.36 | P7: 1.92 | Q7: 1.79 | R7: 1.85 | S7: 2.05 | T7: 2.17 | U7: 2.26 | V7: 2.35 | W7: 2.43 | AA7: =MIN(AA8,AB7,N7) -> 1.79 | AB7: =MIN(AB8,AC7,O7) -> 1.79 | AC7: =MIN(AC8,AD7,P7) -> 1.79 | AD7: =MIN(AD8,AE7,Q7) -> 1.79 | AE7: =MIN(AE8,AF7,R7) -> 1.85 | AF7: =MIN(AF8,AG7,S7) -> 2.05 | AG7: =MIN(AG8,AH7,T7) -> 2.17 | AH7: =MIN(AH8,AI7,U7) -> 2.17 | AI7: =MIN(AI8,AJ7,V7) -> 2.31 | AJ7: =MIN(AJ8,W7) -> 2.43
A8: 34 | B8: 2.86 | C8: 2.1 | D8: 2.1 | E8: 2.67 | F8: 2.53 | G8: 2.29 | H8: 2.65 | I8: 2.17 | J8: 2.31 | K8: 2.47 | M8: 34 | N8: 2.86 | O8: 2.1 | P8: 2.1 | Q8: 2.67 | R8: 2.53 | S8: 2.29 | T8: 2.65 | U8: 2.17 | V8: 2.31 | W8: 2.47 | AA8: =MIN(AA9,AB8,N8) -> 2.1 | AB8: =MIN(AB9,AC8,O8) -> 2.1 | AC8: =MIN(AC9,AD8,P8) -> 2.1 | AD8: =MIN(AD9,AE8,Q8) -> 2.17 | AE8: =MIN(AE9,AF8,R8) -> 2.17 | AF8: =MIN(AF9,AG8,S8) -> 2.17 | AG8: =MIN(AG9,AH8,T8) -> 2.17 | AH8: =MIN(AH9,AI8,U8) -> 2.17 | AI8: =MIN(AI9,AJ8,V8) -> 2.31 | AJ8: =MIN(AJ9,W8) -> 2.46
A9: 38 | B9: 2.46 | C9: 2.46 | D9: 3.23 | E9: 2.46 | F9: 3.21 | G9: 3.19 | H9: 2.46 | I9: 2.46 | J9: 2.46 | K9: 2.46 | M9: 38 | N9: 2.46 | O9: 2.46 | P9: 3.23 | Q9: 2.46 | R9: 3.21 | S9: 3.19 | T9: 2.46 | U9: 2.46 | V9: 2.46 | W9: 2.46 | AA9: =MIN(AA10,AB9,N9) -> 2.46 | AB9: =MIN(AB10,AC9,O9) -> 2.46 | AC9: =MIN(AC10,AD9,P9) -> 2.46 | AD9: =MIN(AD10,AE9,Q9) -> 2.46 | AE9: =MIN(AE10,AF9,R9) -> 2.46 | AF9: =MIN(AF10,AG9,S9) -> 2.46 | AG9: =MIN(AG10,AH9,T9) -> 2.46 | AH9: =MIN(AH10,AI9,U9) -> 2.46 | AI9: =MIN(AI10,AJ9,V9) -> 2.46 | AJ9: =MIN(AJ10,W9) -> 2.46
A10: 42 | B10: 3.54 | C10: 3.54 | D10: 3.63 | E10: 3.68 | F10: 3.53 | G10: 3.71 | H10: 3.69 | I10: 3.6 | J10: 3.66 | K10: 2.84 | M10: 42 | N10: 3.54 | O10: 3.54 | P10: 3.63 | Q10: 3.68 | R10: 3.53 | S10: 3.71 | T10: 3.69 | U10: 3.6 | V10: 3.66 | W10: 2.84 | AA10: =MIN(AA11,AB10,N10) -> 2.52 | AB10: =MIN(AB11,AC10,O10) -> 2.52 | AC10: =MIN(AC11,AD10,P10) -> 2.52 | AD10: =MIN(AD11,AE10,Q10) -> 2.52 | AE10: =MIN(AE11,AF10,R10) -> 2.52 | AF10: =MIN(AF11,AG10,S10) -> 2.78 | AG10: =MIN(AG11,AH10,T10) -> 2.78 | AH10: =MIN(AH11,AI10,U10) -> 2.78 | AI10: =MIN(AI11,AJ10,V10) -> 2.78 | AJ10: =MIN(AJ11,W10) -> 2.78
A11: 46 | B11: 4.11 | C11: 4.68 | D11: 4.09 | E11: 3.69 | F11: 3.99 | G11: 3.91 | H11: 4.13 | I11: 4.23 | J11: 4.37 | K11: 4.1 | M11: 46 | N11: 4.11 | O11: 4.68 | P11: 4.09 | Q11: 3.69 | R11: 3.99 | S11: 3.91 | T11: 4.13 | U11: 4.23 | V11: 4.37 | W11: 4.1 | AA11: =MIN(AA12,AB11,N11) -> 2.52 | AB11: =MIN(AB12,AC11,O11) -> 2.52 | AC11: =MIN(AC12,AD11,P11) -> 2.52 | AD11: =MIN(AD12,AE11,Q11) -> 2.52 | AE11: =MIN(AE12,AF11,R11) -> 2.52 | AF11: =MIN(AF12,AG11,S11) -> 2.78 | AG11: =MIN(AG12,AH11,T11) -> 2.78 | AH11: =MIN(AH12,AI11,U11) -> 2.78 | AI11: =MIN(AI12,AJ11,V11) -> 2.78 | AJ11: =MIN(AJ12,W11) -> 2.78
A12: 50 | B12: 3.63 | C12: 4.49 | D12: 4.78 | E12: 3.63 | F12: 3.71 | G12: 3.85 | H12: 5.02 | I12: 4.51 | J12: 4.89 | K12: 5.3 | M12: 50 | N12: 3.63 | O12: 4.49 | P12: 4.78 | Q12: 3.63 | R12: 3.71 | S12: 3.85 | T12: 5.02 | U12: 4.51 | V12: 4.89 | W12: 5.3 | AA12: =MIN(AA13,AB12,N12) -> 2.52 | AB12: =MIN(AB13,AC12,O12) -> 2.52 | AC12: =MIN(AC13,AD12,P12) -> 2.52 | AD12: =MIN(AD13,AE12,Q12) -> 2.52 | AE12: =MIN(AE13,AF12,R12) -> 2.52 | AF12: =MIN(AF13,AG12,S12) -> 2.78 | AG12: =MIN(AG13,AH12,T12) -> 2.78 | AH12: =MIN(AH13,AI12,U12) -> 2.78 | AI12: =MIN(AI13,AJ12,V12) -> 2.78 | AJ12: =MIN(AJ13,W12) -> 2.78
A13: 54 | B13: 3.57 | C13: 4.03 | D13: 4.03 | E13: 4.18 | F13: 4.03 | G13: 4.03 | H13: 4.5 | I13: 4.03 | J13: 4.3 | K13: 4.03 | M13: 54 | N13: 3.57 | O13: 4.03 | P13: 4.03 | Q13: 4.18 | R13: 4.03 | S13: 4.03 | T13: 4.5 | U13: 4.03 | V13: 4.3 | W13: 4.03 | AA13: =MIN(AA14,AB13,N13) -> 2.52 | AB13: =MIN(AB14,AC13,O13) -> 2.52 | AC13: =MIN(AC14,AD13,P13) -> 2.52 | AD13: =MIN(AD14,AE13,Q13) -> 2.52 | AE13: =MIN(AE14,AF13,R13) -> 2.52 | AF13: =MIN(AF14,AG13,S13) -> 2.78 | AG13: =MIN(AG14,AH13,T13) -> 2.78 | AH13: =MIN(AH14,AI13,U13) -> 2.78 | AI13: =MIN(AI14,AJ13,V13) -> 2.78 | AJ13: =MIN(AJ14,W13) -> 2.78
... A15: 62 | B15: 2.78 | C15: 2.9 | D15: 2.78 | E15: 3.44 | F15: 3.67 | G15: 2.78 | H15: 2.78 | I15: 3.6 | J15: 2.78 | K15: 2.78 | M15: 62 | N15: 2.78 | O15: 2.9 | P15: 2.78 | Q15: 3.44 | R15: 3.67 | S15: 2.78 | T15: 2.78 | U15: 3.6 | V15: 2.78 | W15: 2.78 | AA15: =MIN(AA16,AB15,N15) -> 2.78 | AB15: =MIN(AB16,AC15,O15) -> 2.78 | AC15: =MIN(AC16,AD15,P15) -> 2.78 | AD15: =MIN(AD16,AE15,Q15) -> 2.78 | AE15: =MIN(AE16,AF15,R15) -> 2.78 | AF15: =MIN(AF16,AG15,S15) -> 2.78 | AG15: =MIN(AG16,AH15,T15) -> 2.78 | AH15: =MIN(AH16,AI15,U15) -> 2.78 | AI15: =MIN(AI16,AJ15,V15) -> 2.78 | AJ15: =MIN(AJ16,W15) -> 2.78
A16: 66 | B16: 3.11 | C16: 3.86 | D16: 3.74 | E16: 3.81 | F16: 3.75 | G16: 3.03 | H16: 3.85 | I16: 3.77 | J16: 4.2 | K16: 3.03 | M16: 66 | N16: 3.11 | O16: 3.86 | P16: 3.74 | Q16: 3.81 | R16: 3.75 | S16: 3.03 | T16: 3.85 | U16: 3.77 | V16: 4.2 | W16: 3.03 | AA16: =MIN(N16,AB16) -> 3.03 | AB16: =MIN(O16,AC16) -> 3.03 | AC16: =MIN(P16,AD16) -> 3.03 | AD16: =MIN(Q16,AE16) -> 3.03 | AE16: =MIN(R16,AF16) -> 3.03 | AF16: =MIN(S16,AG16) -> 3.03 | AG16: =MIN(T16,AH16) -> 3.03 | AH16: =MIN(U16,AI16) -> 3.03 | AI16: =MIN(V16,AJ16) -> 3.03 | AJ16: =W16 -> 3.03
B22: =B1 -> 5
A23: =A2 -> 10 | B23: =VLOOKUP("0"&"_"&$B$22&"_"&$A23,Лист2!$A$2:$Q$301,COLUMN()-COLUMN($A23)+1,FALSE) -> 0 | C23: =VLOOKUP("0"&"_"&$B$22&"_"&$A23,Лист2!$A$2:$Q$301,COLUMN()-COLUMN($A23)+1,FALSE) -> 1.48 | D23: =VLOOKUP("0"&"_"&$B$22&"_"&$A23,Лист2!$A$2:$Q$301,COLUMN()-COLUMN($A23)+1,FALSE) -> 4148 | E23: =VLOOKUP("0"&"_"&$B$22&"_"&$A23,Лист2!$A$2:$Q$301,COLUMN()-COLUMN($A23)+1,FALSE) -> 0.78 | F23: =VLOOKUP("0"&"_"&$B$22&"_"&$A23,Лист2!$A$2:$Q$301,COLUMN()-COLUMN($A23)+1,FALSE) -> 1.58 | G23: =VLOOKUP("0"&"_"&$B$22&"_"&$A23,Лист2!$A$2:$Q$301,COLUMN()-COLUMN($A23)+1,FALSE) -> 1.58 | H23: =VLOOKUP("0"&"_"&$B$22&"_"&$A23,Лист2!$A$2:$Q$301,COLUMN()-COLUMN($A23)+1,FALSE) -> 2.35 | I23: =VLOOKUP("0"&"_"&$B$22&"_"&$A23,Лист2!$A$2:$Q$301,COLUMN()-COLUMN($A23)+1,FALSE) -> 2.35 | ... Q23: =VLOOKUP("0"&"_"&$B$22&"_"&$A23,Лист2!$A$2:$Q$301,COLUMN()-COLUMN($A23)+1,FALSE) -> 1
A24: =A3 -> 14 | B24: =VLOOKUP("0"&"_"&$B$22&"_"&$A24,Лист2!$A$2:$Q$301,COLUMN()-COLUMN($A24)+1,FALSE) -> 0 | C24: =VLOOKUP("0"&"_"&$B$22&"_"&$A24,Лист2!$A$2:$Q$301,COLUMN()-COLUMN($A24)+1,FALSE) -> 1.71 | D24: =VLOOKUP("0"&"_"&$B$22&"_"&$A24,Лист2!$A$2:$Q$301,COLUMN()-COLUMN($A24)+1,FALSE) -> 5153 | E24: =VLOOKUP("0"&"_"&$B$22&"_"&$A24,Лист2!$A$2:$Q$301,COLUMN()-COLUMN($A24)+1,FALSE) -> 0.97 | F24: =VLOOKUP("0"&"_"&$B$22&"_"&$A24,Лист2!$A$2:$Q$301,COLUMN()-COLUMN($A24)+1,FALSE) -> 1.67 | G24: =VLOOKUP("0"&"_"&$B$22&"_"&$A24,Лист2!$A$2:$Q$301,COLUMN()-COLUMN($A24)+1,FALSE) -> 1.67 | H24: =VLOOKUP("0"&"_"&$B$22&"_"&$A24,Лист2!$A$2:$Q$301,COLUMN()-COLUMN($A24)+1,FALSE) -> 2.86 | I24: =VLOOKUP("0"&"_"&$B$22&"_"&$A24,Лист2!$A$2:$Q$301,COLUMN()-COLUMN($A24)+1,FALSE) -> 2.86 | ... Q24: =VLOOKUP("0"&"_"&$B$22&"_"&$A24,Лист2!$A$2:$Q$301,COLUMN()-COLUMN($A24)+1,FALSE) -> 1
A25: =A4 -> 18 | B25: =VLOOKUP("0"&"_"&$B$22&"_"&$A25,Лист2!$A$2:$Q$301,COLUMN()-COLUMN($A25)+1,FALSE) -> 0 | C25: =VLOOKUP("0"&"_"&$B$22&"_"&$A25,Лист2!$A$2:$Q$301,COLUMN()-COLUMN($A25)+1,FALSE) -> 1.61 | D25: =VLOOKUP("0"&"_"&$B$22&"_"&$A25,Лист2!$A$2:$Q$301,COLUMN()-COLUMN($A25)+1,FALSE) -> 4799 | E25: =VLOOKUP("0"&"_"&$B$22&"_"&$A25,Лист2!$A$2:$Q$301,COLUMN()-COLUMN($A25)+1,FALSE) -> 0.91 | F25: =VLOOKUP("0"&"_"&$B$22&"_"&$A25,Лист2!$A$2:$Q$301,COLUMN()-COLUMN($A25)+1,FALSE) -> 2.28 | G25: =VLOOKUP("0"&"_"&$B$22&"_"&$A25,Лист2!$A$2:$Q$301,COLUMN()-COLUMN($A25)+1,FALSE) -> 2.28 | H25: =VLOOKUP("0"&"_"&$B$22&"_"&$A25,Лист2!$A$2:$Q$301,COLUMN()-COLUMN($A25)+1,FALSE) -> 3.68 | I25: =VLOOKUP("0"&"_"&$B$22&"_"&$A25,Лист2!$A$2:$Q$301,COLUMN()-COLUMN($A25)+1,FALSE) -> 3.68 | ... Q25: =VLOOKUP("0"&"_"&$B$22&"_"&$A25,Лист2!$A$2:$Q$301,COLUMN()-COLUMN($A25)+1,FALSE) -> 1
A26: =A5 -> 22 | B26: =VLOOKUP("0"&"_"&$B$22&"_"&$A26,Лист2!$A$2:$Q$301,COLUMN()-COLUMN($A26)+1,FALSE) -> 0 | C26: =VLOOKUP("0"&"_"&$B$22&"_"&$A26,Лист2!$A$2:$Q$301,COLUMN()-COLUMN($A26)+1,FALSE) -> 1.47 | D26: =VLOOKUP("0"&"_"&$B$22&"_"&$A26,Лист2!$A$2:$Q$301,COLUMN()-COLUMN($A26)+1,FALSE) -> 4222 | E26: =VLOOKUP("0"&"_"&$B$22&"_"&$A26,Лист2!$A$2:$Q$301,COLUMN()-COLUMN($A26)+1,FALSE) -> 0.8 | F26: =VLOOKUP("0"&"_"&$B$22&"_"&$A26,Лист2!$A$2:$Q$301,COLUMN()-COLUMN($A26)+1,FALSE) -> 3.11 | G26: =VLOOKUP("0"&"_"&$B$22&"_"&$A26,Лист2!$A$2:$Q$301,COLUMN()-COLUMN($A26)+1,FALSE) -> 3.11 | H26: =VLOOKUP("0"&"_"&$B$22&"_"&$A26,Лист2!$A$2:$Q$301,COLUMN()-COLUMN($A26)+1,FALSE) -> 4.56 | I26: =VLOOKUP("0"&"_"&$B$22&"_"&$A26,Лист2!$A$2:$Q$301,COLUMN()-COLUMN($A26)+1,FALSE) -> 4.56 | ... Q26: =VLOOKUP("0"&"_"&$B$22&"_"&$A26,Лист2!$A$2:$Q$301,COLUMN()-COLUMN($A26)+1,FALSE) -> 1
A27: =A6 -> 26 | B27: =VLOOKUP("0"&"_"&$B$22&"_"&$A27,Лист2!$A$2:$Q$301,COLUMN()-COLUMN($A27)+1,FALSE) -> 0 | C27: =VLOOKUP("0"&"_"&$B$22&"_"&$A27,Лист2!$A$2:$Q$301,COLUMN()-COLUMN($A27)+1,FALSE) -> 1.26 | D27: =VLOOKUP("0"&"_"&$B$22&"_"&$A27,Лист2!$A$2:$Q$301,COLUMN()-COLUMN($A27)+1,FALSE) -> 3162 | E27: =VLOOKUP("0"&"_"&$B$22&"_"&$A27,Лист2!$A$2:$Q$301,COLUMN()-COLUMN($A27)+1,FALSE) -> 0.6 | F27: =VLOOKUP("0"&"_"&$B$22&"_"&$A27,Лист2!$A$2:$Q$301,COLUMN()-COLUMN($A27)+1,FALSE) -> 4.74 | G27: =VLOOKUP("0"&"_"&$B$22&"_"&$A27,Лист2!$A$2:$Q$301,COLUMN()-COLUMN($A27)+1,FALSE) -> 4.74 | H27: =VLOOKUP("0"&"_"&$B$22&"_"&$A27,Лист2!$A$2:$Q$301,COLUMN()-COLUMN($A27)+1,FALSE) -> 5.95 | I27: =VLOOKUP("0"&"_"&$B$22&"_"&$A27,Лист2!$A$2:$Q$301,COLUMN()-COLUMN($A27)+1,FALSE) -> 5.95 | ... Q27: =VLOOKUP("0"&"_"&$B$22&"_"&$A27,Лист2!$A$2:$Q$301,COLUMN()-COLUMN($A27)+1,FALSE) -> 1
A28: =A7 -> 30 | B28: =VLOOKUP("0"&"_"&$B$22&"_"&$A28,Лист2!$A$2:$Q$301,COLUMN()-COLUMN($A28)+1,FALSE) -> 0 | C28: =VLOOKUP("0"&"_"&$B$22&"_"&$A28,Лист2!$A$2:$Q$301,COLUMN()-COLUMN($A28)+1,FALSE) -> 1.38 | D28: =VLOOKUP("0"&"_"&$B$22&"_"&$A28,Лист2!$A$2:$Q$301,COLUMN()-COLUMN($A28)+1,FALSE) -> 3868 | E28: =VLOOKUP("0"&"_"&$B$22&"_"&$A28,Лист2!$A$2:$Q$301,COLUMN()-COLUMN($A28)+1,FALSE) -> 0.73 | F28: =VLOOKUP("0"&"_"&$B$22&"_"&$A28,Лист2!$A$2:$Q$301,COLUMN()-COLUMN($A28)+1,FALSE) -> 2.35 | G28: =VLOOKUP("0"&"_"&$B$22&"_"&$A28,Лист2!$A$2:$Q$301,COLUMN()-COLUMN($A28)+1,FALSE) -> 2.35 | H28: =VLOOKUP("0"&"_"&$B$22&"_"&$A28,Лист2!$A$2:$Q$301,COLUMN()-COLUMN($A28)+1,FALSE) -> 3.24 | I28: =VLOOKUP("0"&"_"&$B$22&"_"&$A28,Лист2!$A$2:$Q$301,COLUMN()-COLUMN($A28)+1,FALSE) -> 3.24 | ... Q28: =VLOOKUP("0"&"_"&$B$22&"_"&$A28,Лист2!$A$2:$Q$301,COLUMN()-COLUMN($A28)+1,FALSE) -> 2
A29: =A8 -> 34 | B29: =VLOOKUP("0"&"_"&$B$22&"_"&$A29,Лист2!$A$2:$Q$301,COLUMN()-COLUMN($A29)+1,FALSE) -> 0 | C29: =VLOOKUP("0"&"_"&$B$22&"_"&$A29,Лист2!$A$2:$Q$301,COLUMN()-COLUMN($A29)+1,FALSE) -> 1.32 | D29: =VLOOKUP("0"&"_"&$B$22&"_"&$A29,Лист2!$A$2:$Q$301,COLUMN()-COLUMN($A29)+1,FALSE) -> 3565 | E29: =VLOOKUP("0"&"_"&$B$22&"_"&$A29,Лист2!$A$2:$Q$301,COLUMN()-COLUMN($A29)+1,FALSE) -> 0.67 | F29: =VLOOKUP("0"&"_"&$B$22&"_"&$A29,Лист2!$A$2:$Q$301,COLUMN()-COLUMN($A29)+1,FALSE) -> 2.86 | G29: =VLOOKUP("0"&"_"&$B$22&"_"&$A29,Лист2!$A$2:$Q$301,COLUMN()-COLUMN($A29)+1,FALSE) -> 2.86 | H29: =VLOOKUP("0"&"_"&$B$22&"_"&$A29,Лист2!$A$2:$Q$301,COLUMN()-COLUMN($A29)+1,FALSE) -> 3.77 | I29: =VLOOKUP("0"&"_"&$B$22&"_"&$A29,Лист2!$A$2:$Q$301,COLUMN()-COLUMN($A29)+1,FALSE) -> 3.77 | ... Q29: =VLOOKUP("0"&"_"&$B$22&"_"&$A29,Лист2!$A$2:$Q$301,COLUMN()-COLUMN($A29)+1,FALSE) -> 2
A30: =A9 -> 38 | B30: =VLOOKUP("0"&"_"&$B$22&"_"&$A30,Лист2!$A$2:$Q$301,COLUMN()-COLUMN($A30)+1,FALSE) -> 0 | C30: =VLOOKUP("0"&"_"&$B$22&"_"&$A30,Лист2!$A$2:$Q$301,COLUMN()-COLUMN($A30)+1,FALSE) -> 1.58 | D30: =VLOOKUP("0"&"_"&$B$22&"_"&$A30,Лист2!$A$2:$Q$301,COLUMN()-COLUMN($A30)+1,FALSE) -> 4671 | E30: =VLOOKUP("0"&"_"&$B$22&"_"&$A30,Лист2!$A$2:$Q$301,COLUMN()-COLUMN($A30)+1,FALSE) -> 0.88 | F30: =VLOOKUP("0"&"_"&$B$22&"_"&$A30,Лист2!$A$2:$Q$301,COLUMN()-COLUMN($A30)+1,FALSE) -> 2.46 | G30: =VLOOKUP("0"&"_"&$B$22&"_"&$A30,Лист2!$A$2:$Q$301,COLUMN()-COLUMN($A30)+1,FALSE) -> 2.46 | H30: =VLOOKUP("0"&"_"&$B$22&"_"&$A30,Лист2!$A$2:$Q$301,COLUMN()-COLUMN($A30)+1,FALSE) -> 3.89 | I30: =VLOOKUP("0"&"_"&$B$22&"_"&$A30,Лист2!$A$2:$Q$301,COLUMN()-COLUMN($A30)+1,FALSE) -> 3.89 | ... Q30: =VLOOKUP("0"&"_"&$B$22&"_"&$A30,Лист2!$A$2:$Q$301,COLUMN()-COLUMN($A30)+1,FALSE) -> 2
A31: =A10 -> 42 | B31: =VLOOKUP("0"&"_"&$B$22&"_"&$A31,Лист2!$A$2:$Q$301,COLUMN()-COLUMN($A31)+1,FALSE) -> 0 | C31: =VLOOKUP("0"&"_"&$B$22&"_"&$A31,Лист2!$A$2:$Q$301,COLUMN()-COLUMN($A31)+1,FALSE) -> 1.31 | D31: =VLOOKUP("0"&"_"&$B$22&"_"&$A31,Лист2!$A$2:$Q$301,COLUMN()-COLUMN($A31)+1,FALSE) -> 3508 | E31: =VLOOKUP("0"&"_"&$B$22&"_"&$A31,Лист2!$A$2:$Q$301,COLUMN()-COLUMN($A31)+1,FALSE) -> 0.66 | F31: =VLOOKUP("0"&"_"&$B$22&"_"&$A31,Лист2!$A$2:$Q$301,COLUMN()-COLUMN($A31)+1,FALSE) -> 3.54 | G31: =VLOOKUP("0"&"_"&$B$22&"_"&$A31,Лист2!$A$2:$Q$301,COLUMN()-COLUMN($A31)+1,FALSE) -> 3.54 | H31: =VLOOKUP("0"&"_"&$B$22&"_"&$A31,Лист2!$A$2:$Q$301,COLUMN()-COLUMN($A31)+1,FALSE) -> 4.65 | I31: =VLOOKUP("0"&"_"&$B$22&"_"&$A31,Лист2!$A$2:$Q$301,COLUMN()-COLUMN($A31)+1,FALSE) -> 4.65 | ... Q31: =VLOOKUP("0"&"_"&$B$22&"_"&$A31,Лист2!$A$2:$Q$301,COLUMN()-COLUMN($A31)+1,FALSE) -> 2
A32: =A11 -> 46 | B32: =VLOOKUP("0"&"_"&$B$22&"_"&$A32,Лист2!$A$2:$Q$301,COLUMN()-COLUMN($A32)+1,FALSE) -> 0 | C32: =VLOOKUP("0"&"_"&$B$22&"_"&$A32,Лист2!$A$2:$Q$301,COLUMN()-COLUMN($A32)+1,FALSE) -> 1.27 | D32: =VLOOKUP("0"&"_"&$B$22&"_"&$A32,Лист2!$A$2:$Q$301,COLUMN()-COLUMN($A32)+1,FALSE) -> 3274 | E32: =VLOOKUP("0"&"_"&$B$22&"_"&$A32,Лист2!$A$2:$Q$301,COLUMN()-COLUMN($A32)+1,FALSE) -> 0.62 | F32: =VLOOKUP("0"&"_"&$B$22&"_"&$A32,Лист2!$A$2:$Q$301,COLUMN()-COLUMN($A32)+1,FALSE) -> 4.11 | G32: =VLOOKUP("0"&"_"&$B$22&"_"&$A32,Лист2!$A$2:$Q$301,COLUMN()-COLUMN($A32)+1,FALSE) -> 4.11 | H32: =VLOOKUP("0"&"_"&$B$22&"_"&$A32,Лист2!$A$2:$Q$301,COLUMN()-COLUMN($A32)+1,FALSE) -> 5.22 | I32: =VLOOKUP("0"&"_"&$B$22&"_"&$A32,Лист2!$A$2:$Q$301,COLUMN()-COLUMN($A32)+1,FALSE) -> 5.22 | ... Q32: =VLOOKUP("0"&"_"&$B$22&"_"&$A32,Лист2!$A$2:$Q$301,COLUMN()-COLUMN($A32)+1,FALSE) -> 2
A33: =A12 -> 50 | B33: =VLOOKUP("0"&"_"&$B$22&"_"&$A33,Лист2!$A$2:$Q$301,COLUMN()-COLUMN($A33)+1,FALSE) -> 0 | C33: =VLOOKUP("0"&"_"&$B$22&"_"&$A33,Лист2!$A$2:$Q$301,COLUMN()-COLUMN($A33)+1,FALSE) -> 1.43 | D33: =VLOOKUP("0"&"_"&$B$22&"_"&$A33,Лист2!$A$2:$Q$301,COLUMN()-COLUMN($A33)+1,FALSE) -> 4072 | E33: =VLOOKUP("0"&"_"&$B$22&"_"&$A33,Лист2!$A$2:$Q$301,COLUMN()-COLUMN($A33)+1,FALSE) -> 0.77 | F33: =VLOOKUP("0"&"_"&$B$22&"_"&$A33,Лист2!$A$2:$Q$301,COLUMN()-COLUMN($A33)+1,FALSE) -> 3.63 | G33: =VLOOKUP("0"&"_"&$B$22&"_"&$A33,Лист2!$A$2:$Q$301,COLUMN()-COLUMN($A33)+1,FALSE) -> 3.63 | H33: =VLOOKUP("0"&"_"&$B$22&"_"&$A33,Лист2!$A$2:$Q$301,COLUMN()-COLUMN($A33)+1,FALSE) -> 5.2 | I33: =VLOOKUP("0"&"_"&$B$22&"_"&$A33,Лист2!$A$2:$Q$301,COLUMN()-COLUMN($A33)+1,FALSE) -> 5.2 | ... Q33: =VLOOKUP("0"&"_"&$B$22&"_"&$A33,Лист2!$A$2:$Q$301,COLUMN()-COLUMN($A33)+1,FALSE) -> 2
A34: =A13 -> 54 | B34: =VLOOKUP("0"&"_"&$B$22&"_"&$A34,Лист2!$A$2:$Q$301,COLUMN()-COLUMN($A34)+1,FALSE) -> 0 | C34: =VLOOKUP("0"&"_"&$B$22&"_"&$A34,Лист2!$A$2:$Q$301,COLUMN()-COLUMN($A34)+1,FALSE) -> 1.56 | D34: =VLOOKUP("0"&"_"&$B$22&"_"&$A34,Лист2!$A$2:$Q$301,COLUMN()-COLUMN($A34)+1,FALSE) -> 3382 | E34: =VLOOKUP("0"&"_"&$B$22&"_"&$A34,Лист2!$A$2:$Q$301,COLUMN()-COLUMN($A34)+1,FALSE) -> 0.64 | F34: =VLOOKUP("0"&"_"&$B$22&"_"&$A34,Лист2!$A$2:$Q$301,COLUMN()-COLUMN($A34)+1,FALSE) -> 3.57 | G34: =VLOOKUP("0"&"_"&$B$22&"_"&$A34,Лист2!$A$2:$Q$301,COLUMN()-COLUMN($A34)+1,FALSE) -> 3.57 | H34: =VLOOKUP("0"&"_"&$B$22&"_"&$A34,Лист2!$A$2:$Q$301,COLUMN()-COLUMN($A34)+1,FALSE) -> 5.58 | I34: =VLOOKUP("0"&"_"&$B$22&"_"&$A34,Лист2!$A$2:$Q$301,COLUMN()-COLUMN($A34)+1,FALSE) -> 5.58 | ... Q34: =VLOOKUP("0"&"_"&$B$22&"_"&$A34,Лист2!$A$2:$Q$301,COLUMN()-COLUMN($A34)+1,FALSE) -> 4
... A37: =A16 -> 66 | B37: =VLOOKUP("0"&"_"&$B$22&"_"&$A37,Лист2!$A$2:$Q$301,COLUMN()-COLUMN($A37)+1,FALSE) -> 0 | C37: =VLOOKUP("0"&"_"&$B$22&"_"&$A37,Лист2!$A$2:$Q$301,COLUMN()-COLUMN($A37)+1,FALSE) -> 1.47 | D37: =VLOOKUP("0"&"_"&$B$22&"_"&$A37,Лист2!$A$2:$Q$301,COLUMN()-COLUMN($A37)+1,FALSE) -> 4222 | E37: =VLOOKUP("0"&"_"&$B$22&"_"&$A37,Лист2!$A$2:$Q$301,COLUMN()-COLUMN($A37)+1,FALSE) -> 0.8 | F37: =VLOOKUP("0"&"_"&$B$22&"_"&$A37,Лист2!$A$2:$Q$301,COLUMN()-COLUMN($A37)+1,FALSE) -> 3.11 | G37: =VLOOKUP("0"&"_"&$B$22&"_"&$A37,Лист2!$A$2:$Q$301,COLUMN()-COLUMN($A37)+1,FALSE) -> 3.11 | H37: =VLOOKUP("0"&"_"&$B$22&"_"&$A37,Лист2!$A$2:$Q$301,COLUMN()-COLUMN($A37)+1,FALSE) -> 4.56 | I37: =VLOOKUP("0"&"_"&$B$22&"_"&$A37,Лист2!$A$2:$Q$301,COLUMN()-COLUMN($A37)+1,FALSE) -> 4.56 | ... Q37: =VLOOKUP("0"&"_"&$B$22&"_"&$A37,Лист2!$A$2:$Q$301,COLUMN()-COLUMN($A37)+1,FALSE) -> 3
B41: =B22 -> 5
A42: =A23 -> 10 | B42: =VLOOKUP("1"&"_"&$B$22&"_"&$A23,Лист2!$A$2:$Q$301,COLUMN()-COLUMN($A23)+1,FALSE) -> 1 | C42: =VLOOKUP("1"&"_"&$B$22&"_"&$A23,Лист2!$A$2:$Q$301,COLUMN()-COLUMN($A23)+1,FALSE) -> 2.19 | D42: =VLOOKUP("1"&"_"&$B$22&"_"&$A23,Лист2!$A$2:$Q$301,COLUMN()-COLUMN($A23)+1,FALSE) -> 5565 | E42: =VLOOKUP("1"&"_"&$B$22&"_"&$A23,Лист2!$A$2:$Q$301,COLUMN()-COLUMN($A23)+1,FALSE) -> 1.05 | F42: =VLOOKUP("1"&"_"&$B$22&"_"&$A23,Лист2!$A$2:$Q$301,COLUMN()-COLUMN($A23)+1,FALSE) -> 2.29 | G42: =VLOOKUP("1"&"_"&$B$22&"_"&$A23,Лист2!$A$2:$Q$301,COLUMN()-COLUMN($A23)+1,FALSE) -> 2.29 | H42: =VLOOKUP("1"&"_"&$B$22&"_"&$A23,Лист2!$A$2:$Q$301,COLUMN()-COLUMN($A23)+1,FALSE) -> 5 | I42: =VLOOKUP("1"&"_"&$B$22&"_"&$A23,Лист2!$A$2:$Q$301,COLUMN()-COLUMN($A23)+1,FALSE) -> 5 | ... Q42: =VLOOKUP("1"&"_"&$B$22&"_"&$A23,Лист2!$A$2:$Q$301,COLUMN()-COLUMN($A23)+1,FALSE) -> 1
A43: =A24 -> 14 | B43: =VLOOKUP("1"&"_"&$B$22&"_"&$A24,Лист2!$A$2:$Q$301,COLUMN()-COLUMN($A24)+1,FALSE) -> 1 | C43: =VLOOKUP("1"&"_"&$B$22&"_"&$A24,Лист2!$A$2:$Q$301,COLUMN()-COLUMN($A24)+1,FALSE) -> 1.88 | D43: =VLOOKUP("1"&"_"&$B$22&"_"&$A24,Лист2!$A$2:$Q$301,COLUMN()-COLUMN($A24)+1,FALSE) -> 5419 | E43: =VLOOKUP("1"&"_"&$B$22&"_"&$A24,Лист2!$A$2:$Q$301,COLUMN()-COLUMN($A24)+1,FALSE) -> 1.02 | F43: =VLOOKUP("1"&"_"&$B$22&"_"&$A24,Лист2!$A$2:$Q$301,COLUMN()-COLUMN($A24)+1,FALSE) -> 2.8 | G43: =VLOOKUP("1"&"_"&$B$22&"_"&$A24,Лист2!$A$2:$Q$301,COLUMN()-COLUMN($A24)+1,FALSE) -> 2.8 | H43: =VLOOKUP("1"&"_"&$B$22&"_"&$A24,Лист2!$A$2:$Q$301,COLUMN()-COLUMN($A24)+1,FALSE) -> 5.26 | I43: =VLOOKUP("1"&"_"&$B$22&"_"&$A24,Лист2!$A$2:$Q$301,COLUMN()-COLUMN($A24)+1,FALSE) -> 5.26 | ... Q43: =VLOOKUP("1"&"_"&$B$22&"_"&$A24,Лист2!$A$2:$Q$301,COLUMN()-COLUMN($A24)+1,FALSE) -> 1
A44: =A25 -> 18 | B44: =VLOOKUP("1"&"_"&$B$22&"_"&$A25,Лист2!$A$2:$Q$301,COLUMN()-COLUMN($A25)+1,FALSE) -> 1 | C44: =VLOOKUP("1"&"_"&$B$22&"_"&$A25,Лист2!$A$2:$Q$301,COLUMN()-COLUMN($A25)+1,FALSE) -> 1.61 | D44: =VLOOKUP("1"&"_"&$B$22&"_"&$A25,Лист2!$A$2:$Q$301,COLUMN()-COLUMN($A25)+1,FALSE) -> 4940 | E44: =VLOOKUP("1"&"_"&$B$22&"_"&$A25,Лист2!$A$2:$Q$301,COLUMN()-COLUMN($A25)+1,FALSE) -> 0.93 | F44: =VLOOKUP("1"&"_"&$B$22&"_"&$A25,Лист2!$A$2:$Q$301,COLUMN()-COLUMN($A25)+1,FALSE) -> 3.62 | G44: =VLOOKUP("1"&"_"&$B$22&"_"&$A25,Лист2!$A$2:$Q$301,COLUMN()-COLUMN($A25)+1,FALSE) -> 3.62 | H44: =VLOOKUP("1"&"_"&$B$22&"_"&$A25,Лист2!$A$2:$Q$301,COLUMN()-COLUMN($A25)+1,FALSE) -> 5.8 | I44: =VLOOKUP("1"&"_"&$B$22&"_"&$A25,Лист2!$A$2:$Q$301,COLUMN()-COLUMN($A25)+1,FALSE) -> 5.8 | ... Q44: =VLOOKUP("1"&"_"&$B$22&"_"&$A25,Лист2!$A$2:$Q$301,COLUMN()-COLUMN($A25)+1,FALSE) -> 1
A45: =A26 -> 22 | B45: =VLOOKUP("1"&"_"&$B$22&"_"&$A26,Лист2!$A$2:$Q$301,COLUMN()-COLUMN($A26)+1,FALSE) -> 1 | C45: =VLOOKUP("1"&"_"&$B$22&"_"&$A26,Лист2!$A$2:$Q$301,COLUMN()-COLUMN($A26)+1,FALSE) -> 1.47 | D45: =VLOOKUP("1"&"_"&$B$22&"_"&$A26,Лист2!$A$2:$Q$301,COLUMN()-COLUMN($A26)+1,FALSE) -> 4591 | E45: =VLOOKUP("1"&"_"&$B$22&"_"&$A26,Лист2!$A$2:$Q$301,COLUMN()-COLUMN($A26)+1,FALSE) -> 0.87 | F45: =VLOOKUP("1"&"_"&$B$22&"_"&$A26,Лист2!$A$2:$Q$301,COLUMN()-COLUMN($A26)+1,FALSE) -> 4.5 | G45: =VLOOKUP("1"&"_"&$B$22&"_"&$A26,Лист2!$A$2:$Q$301,COLUMN()-COLUMN($A26)+1,FALSE) -> 4.5 | H45: =VLOOKUP("1"&"_"&$B$22&"_"&$A26,Лист2!$A$2:$Q$301,COLUMN()-COLUMN($A26)+1,FALSE) -> 6.64 | I45: =VLOOKUP("1"&"_"&$B$22&"_"&$A26,Лист2!$A$2:$Q$301,COLUMN()-COLUMN($A26)+1,FALSE) -> 6.64 | ... Q45: =VLOOKUP("1"&"_"&$B$22&"_"&$A26,Лист2!$A$2:$Q$301,COLUMN()-COLUMN($A26)+1,FALSE) -> 1
A46: =A27 -> 26 | B46: =VLOOKUP("1"&"_"&$B$22&"_"&$A27,Лист2!$A$2:$Q$301,COLUMN()-COLUMN($A27)+1,FALSE) -> 1 | C46: =VLOOKUP("1"&"_"&$B$22&"_"&$A27,Лист2!$A$2:$Q$301,COLUMN()-COLUMN($A27)+1,FALSE) -> 1.31 | D46: =VLOOKUP("1"&"_"&$B$22&"_"&$A27,Лист2!$A$2:$Q$301,COLUMN()-COLUMN($A27)+1,FALSE) -> 3886 | E46: =VLOOKUP("1"&"_"&$B$22&"_"&$A27,Лист2!$A$2:$Q$301,COLUMN()-COLUMN($A27)+1,FALSE) -> 0.73 | F46: =VLOOKUP("1"&"_"&$B$22&"_"&$A27,Лист2!$A$2:$Q$301,COLUMN()-COLUMN($A27)+1,FALSE) -> 5.89 | G46: =VLOOKUP("1"&"_"&$B$22&"_"&$A27,Лист2!$A$2:$Q$301,COLUMN()-COLUMN($A27)+1,FALSE) -> 5.89 | H46: =VLOOKUP("1"&"_"&$B$22&"_"&$A27,Лист2!$A$2:$Q$301,COLUMN()-COLUMN($A27)+1,FALSE) -> 7.7 | I46: =VLOOKUP("1"&"_"&$B$22&"_"&$A27,Лист2!$A$2:$Q$301,COLUMN()-COLUMN($A27)+1,FALSE) -> 7.7 | ... Q46: =VLOOKUP("1"&"_"&$B$22&"_"&$A27,Лист2!$A$2:$Q$301,COLUMN()-COLUMN($A27)+1,FALSE) -> 1
A47: =A28 -> 30 | B47: =VLOOKUP("1"&"_"&$B$22&"_"&$A28,Лист2!$A$2:$Q$301,COLUMN()-COLUMN($A28)+1,FALSE) -> 1 | C47: =VLOOKUP("1"&"_"&$B$22&"_"&$A28,Лист2!$A$2:$Q$301,COLUMN()-COLUMN($A28)+1,FALSE) -> 2.42 | D47: =VLOOKUP("1"&"_"&$B$22&"_"&$A28,Лист2!$A$2:$Q$301,COLUMN()-COLUMN($A28)+1,FALSE) -> 5439 | E47: =VLOOKUP("1"&"_"&$B$22&"_"&$A28,Лист2!$A$2:$Q$301,COLUMN()-COLUMN($A28)+1,FALSE) -> 1.03 | F47: =VLOOKUP("1"&"_"&$B$22&"_"&$A28,Лист2!$A$2:$Q$301,COLUMN()-COLUMN($A28)+1,FALSE) -> 3.18 | G47: =VLOOKUP("1"&"_"&$B$22&"_"&$A28,Лист2!$A$2:$Q$301,COLUMN()-COLUMN($A28)+1,FALSE) -> 3.18 | H47: =VLOOKUP("1"&"_"&$B$22&"_"&$A28,Лист2!$A$2:$Q$301,COLUMN()-COLUMN($A28)+1,FALSE) -> 7.7 | I47: =VLOOKUP("1"&"_"&$B$22&"_"&$A28,Лист2!$A$2:$Q$301,COLUMN()-COLUMN($A28)+1,FALSE) -> 7.7 | ... Q47: =VLOOKUP("1"&"_"&$B$22&"_"&$A28,Лист2!$A$2:$Q$301,COLUMN()-COLUMN($A28)+1,FALSE) -> 3
A48: =A29 -> 34 | B48: =VLOOKUP("1"&"_"&$B$22&"_"&$A29,Лист2!$A$2:$Q$301,COLUMN()-COLUMN($A29)+1,FALSE) -> 1 | C48: =VLOOKUP("1"&"_"&$B$22&"_"&$A29,Лист2!$A$2:$Q$301,COLUMN()-COLUMN($A29)+1,FALSE) -> 1.71 | D48: =VLOOKUP("1"&"_"&$B$22&"_"&$A29,Лист2!$A$2:$Q$301,COLUMN()-COLUMN($A29)+1,FALSE) -> 4903 | E48: =VLOOKUP("1"&"_"&$B$22&"_"&$A29,Лист2!$A$2:$Q$301,COLUMN()-COLUMN($A29)+1,FALSE) -> 0.93 | F48: =VLOOKUP("1"&"_"&$B$22&"_"&$A29,Лист2!$A$2:$Q$301,COLUMN()-COLUMN($A29)+1,FALSE) -> 3.71 | G48: =VLOOKUP("1"&"_"&$B$22&"_"&$A29,Лист2!$A$2:$Q$301,COLUMN()-COLUMN($A29)+1,FALSE) -> 3.71 | H48: =VLOOKUP("1"&"_"&$B$22&"_"&$A29,Лист2!$A$2:$Q$301,COLUMN()-COLUMN($A29)+1,FALSE) -> 6.35 | I48: =VLOOKUP("1"&"_"&$B$22&"_"&$A29,Лист2!$A$2:$Q$301,COLUMN()-COLUMN($A29)+1,FALSE) -> 6.35 | ... Q48: =VLOOKUP("1"&"_"&$B$22&"_"&$A29,Лист2!$A$2:$Q$301,COLUMN()-COLUMN($A29)+1,FALSE) -> 2
A49: =A30 -> 38 | B49: =VLOOKUP("1"&"_"&$B$22&"_"&$A30,Лист2!$A$2:$Q$301,COLUMN()-COLUMN($A30)+1,FALSE) -> 1 | C49: =VLOOKUP("1"&"_"&$B$22&"_"&$A30,Лист2!$A$2:$Q$301,COLUMN()-COLUMN($A30)+1,FALSE) -> 1.57 | D49: =VLOOKUP("1"&"_"&$B$22&"_"&$A30,Лист2!$A$2:$Q$301,COLUMN()-COLUMN($A30)+1,FALSE) -> 4860 | E49: =VLOOKUP("1"&"_"&$B$22&"_"&$A30,Лист2!$A$2:$Q$301,COLUMN()-COLUMN($A30)+1,FALSE) -> 0.92 | F49: =VLOOKUP("1"&"_"&$B$22&"_"&$A30,Лист2!$A$2:$Q$301,COLUMN()-COLUMN($A30)+1,FALSE) -> 3.83 | G49: =VLOOKUP("1"&"_"&$B$22&"_"&$A30,Лист2!$A$2:$Q$301,COLUMN()-COLUMN($A30)+1,FALSE) -> 3.83 | H49: =VLOOKUP("1"&"_"&$B$22&"_"&$A30,Лист2!$A$2:$Q$301,COLUMN()-COLUMN($A30)+1,FALSE) -> 6.01 | I49: =VLOOKUP("1"&"_"&$B$22&"_"&$A30,Лист2!$A$2:$Q$301,COLUMN()-COLUMN($A30)+1,FALSE) -> 6.01 | ... Q49: =VLOOKUP("1"&"_"&$B$22&"_"&$A30,Лист2!$A$2:$Q$301,COLUMN()-COLUMN($A30)+1,FALSE) -> 2
A50: =A31 -> 42 | B50: =VLOOKUP("1"&"_"&$B$22&"_"&$A31,Лист2!$A$2:$Q$301,COLUMN()-COLUMN($A31)+1,FALSE) -> 1 | C50: =VLOOKUP("1"&"_"&$B$22&"_"&$A31,Лист2!$A$2:$Q$301,COLUMN()-COLUMN($A31)+1,FALSE) -> 1.32 | D50: =VLOOKUP("1"&"_"&$B$22&"_"&$A31,Лист2!$A$2:$Q$301,COLUMN()-COLUMN($A31)+1,FALSE) -> 4096 | E50: =VLOOKUP("1"&"_"&$B$22&"_"&$A31,Лист2!$A$2:$Q$301,COLUMN()-COLUMN($A31)+1,FALSE) -> 0.77 | F50: =VLOOKUP("1"&"_"&$B$22&"_"&$A31,Лист2!$A$2:$Q$301,COLUMN()-COLUMN($A31)+1,FALSE) -> 4.59 | G50: =VLOOKUP("1"&"_"&$B$22&"_"&$A31,Лист2!$A$2:$Q$301,COLUMN()-COLUMN($A31)+1,FALSE) -> 4.59 | H50: =VLOOKUP("1"&"_"&$B$22&"_"&$A31,Лист2!$A$2:$Q$301,COLUMN()-COLUMN($A31)+1,FALSE) -> 6.07 | I50: =VLOOKUP("1"&"_"&$B$22&"_"&$A31,Лист2!$A$2:$Q$301,COLUMN()-COLUMN($A31)+1,FALSE) -> 6.07 | ... Q50: =VLOOKUP("1"&"_"&$B$22&"_"&$A31,Лист2!$A$2:$Q$301,COLUMN()-COLUMN($A31)+1,FALSE) -> 2
A51: =A32 -> 46 | B51: =VLOOKUP("1"&"_"&$B$22&"_"&$A32,Лист2!$A$2:$Q$301,COLUMN()-COLUMN($A32)+1,FALSE) -> 1 | C51: =VLOOKUP("1"&"_"&$B$22&"_"&$A32,Лист2!$A$2:$Q$301,COLUMN()-COLUMN($A32)+1,FALSE) -> 1.33 | D51: =VLOOKUP("1"&"_"&$B$22&"_"&$A32,Лист2!$A$2:$Q$301,COLUMN()-COLUMN($A32)+1,FALSE) -> 3309 | E51: =VLOOKUP("1"&"_"&$B$22&"_"&$A32,Лист2!$A$2:$Q$301,COLUMN()-COLUMN($A32)+1,FALSE) -> 0.62 | F51: =VLOOKUP("1"&"_"&$B$22&"_"&$A32,Лист2!$A$2:$Q$301,COLUMN()-COLUMN($A32)+1,FALSE) -> 5.16 | G51: =VLOOKUP("1"&"_"&$B$22&"_"&$A32,Лист2!$A$2:$Q$301,COLUMN()-COLUMN($A32)+1,FALSE) -> 5.16 | H51: =VLOOKUP("1"&"_"&$B$22&"_"&$A32,Лист2!$A$2:$Q$301,COLUMN()-COLUMN($A32)+1,FALSE) -> 6.88 | I51: =VLOOKUP("1"&"_"&$B$22&"_"&$A32,Лист2!$A$2:$Q$301,COLUMN()-COLUMN($A32)+1,FALSE) -> 6.88 | ... Q51: =VLOOKUP("1"&"_"&$B$22&"_"&$A32,Лист2!$A$2:$Q$301,COLUMN()-COLUMN($A32)+1,FALSE) -> 3
...

Sheet Лист2
B1: stage_num | C1: comp | D1: freq | E1: freq_dimm | F1: p_in | G1: p_in_result | H1: p_out | I1: p_out_diff | J1: p_target | K1: power | L1: q_rate | M1: target | N1: title | O1: udal | P1: volume_rate | Q1: work_gpa
A2: =B2&"_"&J2&"_"&L2 -> 0_5_10 | B2: 0 | C2: 1.48 | D2: 4148 | E2: 0.78 | F2: 1.58 | G2: 1.58 | H2: 2.35 | I2: 2.35 | J2: 5 | K2: 7007.98 | L2: 10 | M2: 2.65 | N2: ./DKS_math/Test/spch_dimkoef/ГПА-16 40-2,5 Южно-Русское.csv | O2: 91.17 | P2: 439.53 | Q2: 1
A3: =B3&"_"&J3&"_"&L3 -> 1_5_10 | B3: 1 | C3: 2.19 | D3: 5565 | E3: 1.05 | F3: 2.29 | G3: 2.29 | H3: 5 | I3: 5 | J3: 5 | K3: 13651.89 | L3: 10 | M3: 0 | N3: ./DKS_math/Test/spch_dimkoef/ГПА-16 76-2,2 (01) ЮжРус(новая).csv | O3: 56.25 | P3: 299.32 | Q3: 1
A4: =B4&"_"&J4&"_"&L4 -> 0_5.1_10 | B4: 0 | C4: 2.83 | D4: 5565 | E4: 1.05 | F4: 0.84 | G4: 0.84 | H4: 2.37 | I4: 2.37 | J4: 5.1 | K4: 8828.2 | L4: 10 | M4: 2.73 | N4: ./DKS_math/Test/spch_dimkoef/ГПА-16 40-2,5 Южно-Русское.csv | O4: 51.33 | P4: 420.73 | Q4: 2
A5: =B5&"_"&J5&"_"&L5 -> 1_5.1_10 | B5: 1 | C5: 2.2 | D5: 5565 | E5: 1.05 | F5: 2.31 | G5: 2.31 | H5: 5.1 | I5: 5.1 | J5: 5.1 | K5: 13772.34 | L5: 10 | M5: 0 | N5: ./DKS_math/Test/spch_dimkoef/ГПА-16 76-2,2 (01) ЮжРус(новая).csv | O5: 54.78 | P5: 295.75 | Q5: 1
A6: =B6&"_"&J6&"_"&L6 -> 0_5.2_10 | B6: 0 | C6: 1.99 | D6: 5565 | E6: 1.05 | F6: 1.2 | G6: 1.2 | H6: 2.4 | I6: 2.4 | J6: 5.2 | K6: 12796.21 | L6: 10 | M6: 2.8 | N6: ./DKS_math/Test/spch_dimkoef/ГПА-16 40-2,5 Южно-Русское.csv | O6: 89.26 | P6: 581.51 | Q6: 1
A7: =B7&"_"&J7&"_"&L7 -> 1_5.2_10 | B7: 1 | C7: 2.22 | D7: 5565 | E7: 1.05 | F7: 2.34 | G7: 2.34 | H7: 5.2 | I7: 5.2 | J7: 5.2 | K7: 13891.16 | L7: 10 | M7: 0 | N7: ./DKS_math/Test/spch_dimkoef/ГПА-16 76-2,2 (01) ЮжРус(новая).csv | O7: 53.34 | P7: 292.25 | Q7: 1
A8: =B8&"_"&J8&"_"&L8 -> 0_5.3_10 | B8: 0 | C8: 2.01 | D8: 5565 | E8: 1.05 | F8: 1.21 | G8: 1.21 | H8: 2.43 | I8: 2.43 | J8: 5.3 | K8: 12865.4 | L8: 10 | M8: 2.87 | N8: ./DKS_math/Test/spch_dimkoef/ГПА-16 40-2,5 Южно-Русское.csv | O8: 88.57 | P8: 578.58 | Q8: 1
A9: =B9&"_"&J9&"_"&L9 -> 1_5.3_10 | B9: 1 | C9: 2.24 | D9: 5565 | E9: 1.05 | F9: 2.37 | G9: 2.37 | H9: 5.3 | I9: 5.3 | J9: 5.3 | K9: 14008.44 | L9: 10 | M9: 0 | N9: ./DKS_math/Test/spch_dimkoef/ГПА-16 76-2,2 (01) ЮжРус(новая).csv | O9: 51.92 | P9: 288.8 | Q9: 1
A10: =B10&"_"&J10&"_"&L10 -> 0_5.4_10 | B10: 0 | C10: 2.02 | D10: 5565 | E10: 1.05 | F10: 1.22 | G10: 1.22 | H10: 2.45 | I10: 2.45 | J10: 5.4 | K10: 12934.03 | L10: 10 | M10: 2.95 | N10: ./DKS_math/Test/spch_dimkoef/ГПА-16 40-2,5 Южно-Русское.csv | O10: 87.89 | P10: 575.68 | Q10: 1
A11: =B11&"_"&J11&"_"&L11 -> 1_5.4_10 | B11: 1 | C11: 2.26 | D11: 5565 | E11: 1.05 | F11: 2.39 | G11: 2.39 | H11: 5.4 | I11: 5.4 | J11: 5.4 | K11: 14124.23 | L11: 10 | M11: 0 | N11: ./DKS_math/Test/spch_dimkoef/ГПА-16 76-2,2 (01) ЮжРус(новая).csv | O11: 50.52 | P11: 285.4 | Q11: 1
A12: =B12&"_"&J12&"_"&L12 -> 0_5.5_10 | B12: 0 | C12: 2.03 | D12: 5565 | E12: 1.05 | F12: 1.22 | G12: 1.22 | H12: 2.48 | I12: 2.48 | J12: 5.5 | K12: 13004.61 | L12: 10 | M12: 3.02 | N12: ./DKS_math/Test/spch_dimkoef/ГПА-16 40-2,5 Южно-Русское.csv | O12: 87.22 | P12: 572.86 | Q12: 1
A13: =B13&"_"&J13&"_"&L13 -> 1_5.5_10 | B13: 1 | C13: 2.27 | D13: 5565 | E13: 1.05 | F13: 2.42 | G13: 2.42 | H13: 5.5 | I13: 5.5 | J13: 5.5 | K13: 14238.58 | L13: 10 | M13: 0 | N13: ./DKS_math/Test/spch_dimkoef/ГПА-16 76-2,2 (01) ЮжРус(новая).csv | O13: 49.14 | P13: 282.06 | Q13: 1
... A301: =B301&"_"&J301&"_"&L301 -> 1_5.9_66 | B301: 1 | C301: 1.46 | D301: 4579 | E301: 0.86 | F301: 4.47 | G301: 4.47 | H301: 6.53 | I301: 6.53 | J301: 5.9 | K301: 15716.51 | L301: 66 | M301: 0.63 | N301: ./DKS_math/Test/spch_dimkoef/ГПА-16 76-2,2 (01) ЮжРус(новая).csv | O301: 93.89 | P301: 321.43 | Q301: 3

Sheet Лист3
A1: q_rate | B1: 5 | C1: 5.1 | D1: 5.2 | E1: 5.3 | F1: 5.4 | G1: 5.5 | H1: 5.6 | I1: 5.7 | J1: 5.8 | K1: 5.9 | N1: =B1 -> 5 | O1: =C1 -> 5.1 | P1: =D1 -> 5.2 | Q1: =E1 -> 5.3 | R1: =F1 -> 5.4 | S1: =G1 -> 5.5 | T1: =H1 -> 5.6 | U1: =I1 -> 5.7 | ... W1: =K1 -> 5.9
A2: 20 | B2: 1.6 | C2: 1.65 | D2: 1.65 | E2: 1.65 | F2: 1.65 | G2: 2.15 | H2: 2.16 | I2: 2.16 | J2: 2.16 | K2: 2.26 | N2: 1.79 | O2: 1.79 | P2: 1.79 | Q2: 1.79 | R2: 1.85 | S2: 2.05 | T2: 2.17 | U2: 2.26 | V2: 2.35 | W2: 2.43 | Y2: 5
A3: 25 | B3: 1.6 | C3: 1.65 | D3: 1.65 | E3: 1.65 | F3: 1.65 | G3: 2.15 | H3: 2.16 | I3: 2.18 | J3: 2.26 | K3: 2.26 | N3: 1.79 | O3: 1.79 | P3: 1.79 | Q3: 1.79 | R3: 1.85 | S3: 2.05 | T3: 2.17 | U3: 2.26 | V3: 2.35 | W3: 2.43
A4: 30 | B4: 2.04 | C4: 2.05 | D4: 2.05 | E4: 2.05 | F4: 2.05 | G4: 2.15 | H4: 2.16 | I4: 2.18 | J4: 2.34 | K4: 2.6 | N4: 1.79 | O4: 1.79 | P4: 1.79 | Q4: 1.79 | R4: 1.85 | S4: 2.05 | T4: 2.17 | U4: 2.26 | V4: 2.35 | W4: 2.43
A5: 35 | B5: 2.05 | C5: 2.05 | D5: 2.05 | E5: 2.05 | F5: 2.05 | G5: 2.2 | H5: 2.33 | I5: 2.33 | J5: 2.34 | K5: 2.6 | N5: 2.19 | O5: 2.19 | P5: 2.19 | Q5: 2.19 | R5: 2.43 | S5: 2.43 | T5: 2.43 | U5: 2.43 | V5: 2.48 | W5: 2.48
A6: 40 | B6: 2.05 | C6: 2.05 | D6: 2.05 | E6: 2.05 | F6: 2.05 | G6: 2.2 | H6: 2.33 | I6: 2.33 | J6: 2.34 | K6: 2.6 | N6: 2.65 | O6: 2.65 | P6: 2.65 | Q6: 2.65 | R6: 2.65 | S6: 2.65 | T6: 2.65 | U6: 2.65 | V6: 2.97 | W6: 2.97
A7: 45 | B7: 2.05 | C7: 2.05 | D7: 2.05 | E7: 2.05 | F7: 2.05 | G7: 2.2 | H7: 2.33 | I7: 2.33 | J7: 2.34 | K7: 2.6 | N7: 2.65 | O7: 2.65 | P7: 2.65 | Q7: 2.65 | R7: 2.65 | S7: 2.65 | T7: 2.65 | U7: 2.65 | V7: 2.97 | W7: 2.97
A8: 50 | B8: 2.05 | C8: 2.05 | D8: 2.05 | E8: 2.05 | F8: 2.05 | G8: 2.2 | H8: 2.43 | I8: 2.43 | J8: 2.43 | K8: 2.6 | N8: 2.65 | O8: 2.65 | P8: 2.65 | Q8: 2.65 | R8: 2.65 | S8: 2.65 | T8: 2.65 | U8: 2.65 | V8: 2.97 | W8: 2.97 | AA8: {=TRANSPOSE(N1:W1)} -> 5
A9: 55 | B9: 2.23 | C9: 2.23 | D9: 2.23 | E9: 2.23 | F9: 2.23 | G9: 2.23 | H9: 2.43 | I9: 2.43 | J9: 2.43 | K9: 2.87 | N9: 2.65 | O9: 2.65 | P9: 2.65 | Q9: 2.65 | R9: 2.65 | S9: 2.65 | T9: 2.65 | U9: 2.65 | V9: 2.97 | W9: 2.97 | AA9: 5.1
A10: 60 | B10: 2.23 | C10: 2.23 | D10: 2.23 | E10: 2.23 | F10: 2.23 | G10: 2.23 | H10: 2.43 | I10: 2.43 | J10: 2.43 | K10: 2.87 | N10: 2.65 | O10: 2.65 | P10: 2.65 | Q10: 2.65 | R10: 2.65 | S10: 2.65 | T10: 2.65 | U10: 2.65 | V10: 2.97 | W10: 2.97 | AA10: 5.2
A11: 65 | B11: 2.23 | C11: 2.23 | D11: 2.23 | E11: 2.23 | F11: 2.23 | G11: 2.23 | H11: 2.43 | I11: 2.43 | J11: 2.43 | K11: 2.87 | N11: 2.97 | O11: 2.97 | P11: 2.97 | Q11: 2.97 | R11: 2.97 | S11: 2.97 | T11: 2.97 | U11: 2.97 | V11: 2.97 | W11: 2.97 | AA11: 5.3
A12: 70 | B12: 2.25 | C12: 2.43 | D12: 2.43 | E12: 2.43 | F12: 2.43 | G12: 2.43 | H12: 2.43 | I12: 2.43 | J12: 2.43 | K12: 2.87 | N12: 3.05 | O12: 3.05 | P12: 3.19 | Q12: 3.19 | R12: 3.19 | S12: 3.29 | T12: 3.29 | U12: 3.29 | V12: 3.29 | W12: 3.97 | AA12: 5.4
A13: 75 | B13: 2.25 | C13: 2.43 | D13: 2.43 | E13: 2.43 | F13: 2.43 | G13: 2.43 | H13: 2.43 | I13: 2.43 | J13: 2.43 | K13: 2.87 | N13: 3.05 | O13: 3.05 | P13: 3.19 | Q13: 3.19 | R13: 3.19 | S13: 3.38 | T13: 3.38 | U13: 3.38 | V13: 3.94 | W13: 3.97 | AA13: 5.5
A14: 80 | B14: 2.43 | C14: 2.43 | D14: 2.43 | E14: 2.43 | F14: 2.43 | G14: 2.43 | H14: 2.43 | I14: 2.43 | J14: 2.43 | K14: 2.87 | N14: 3.05 | O14: 3.05 | P14: 3.19 | Q14: 3.19 | R14: 3.19 | S14: 3.38 | T14: 3.38 | U14: 3.38 | V14: 3.94 | W14: 3.97 | AA14: 5.6
A15: 85 | B15: 2.43 | C15: 2.43 | D15: 2.43 | E15: 2.43 | F15: 2.43 | G15: 2.43 | H15: 2.43 | I15: 2.43 | J15: 2.43 | K15: 2.87 | N15: 3.05 | O15: 3.05 | P15: 3.19 | Q15: 3.19 | R15: 3.19 | S15: 3.38 | T15: 3.38 | U15: 3.38 | V15: 3.94 | W15: 4.08 | AA15: 5.7
A16: 90 | B16: 2.63 | C16: 2.63 | D16: 2.63 | E16: 2.87 | F16: 2.87 | G16: 2.87 | H16: 2.87 | I16: 2.87 | J16: 2.87 | K16: 2.87 | N16: 3.11 | O16: 3.19 | P16: 3.19 | Q16: 3.19 | R16: 3.19 | S16: 3.38 | T16: 3.38 | U16: 3.38 | V16: 3.94 | W16: 4.08 | AA16: 5.8
A17: 95 | B17: 2.87 | C17: 2.87 | D17: 2.87 | E17: 2.87 | F17: 2.87 | G17: 2.87 | H17: 2.87 | I17: 2.87 | J17: 2.87 | K17: 2.87 | N17: 3.11 | O17: 3.38 | P17: 3.38 | Q17: 3.38 | R17: 3.38 | S17: 3.38 | T17: 3.38 | U17: 3.38 | V17: 4.14 | W17: 4.17 | AA17: 5.9
A18: 100 | B18: 2.87 | C18: 2.87 | D18: 2.87 | E18: 2.87 | F18: 2.87 | G18: 2.87 | H18: 2.87 | I18: 2.87 | J18: 2.87 | K18: 2.87 | N18: 3.11 | O18: 3.45 | P18: 3.45 | Q18: 3.45 | R18: 3.45 | S18: 3.45 | T18: 3.88 | U18: 4.14 | V18: 4.14 | W18: 4.17 | AA18: #N/A
A19: 105 | B19: 2.87 | C19: 2.87 | D19: 2.87 | E19: 2.87 | F19: 2.87 | G19: 2.87 | H19: 2.87 | I19: 2.87 | J19: 2.87 | K19: 2.87 | N19: 3.11 | O19: 3.63 | P19: 3.63 | Q19: 3.69 | R19: 3.88 | S19: 3.88 | T19: 3.88 | U19: 4.14 | V19: 4.14 | W19: 4.17 | AA19: #N/A
A20: 110 | B20: 2.87 | C20: 2.87 | D20: 2.87 | E20: 2.87 | F20: 2.87 | G20: 2.87 | H20: 2.87 | I20: 2.87 | J20: 2.87 | K20: 2.87 | N20: 3.11 | O20: 3.69 | P20: 3.69 | Q20: 3.69 | R20: 3.91 | S20: 3.91 | T20: 4.14 | U20: 4.14 | V20: 4.14 | W20: 4.4 | AA20: #N/A
A21: 115 | B21: 3.03 | C21: 3.32 | D21: 3.32 | E21: 3.32 | F21: 3.32 | G21: 3.32 | H21: 3.32 | I21: 3.32 | J21: 3.67 | K21: 4.7 | N21: 3.69 | O21: 3.69 | P21: 3.69 | Q21: 3.69 | R21: 3.91 | S21: 3.91 | T21: 4.23 | U21: 4.23 | V21: 4.4 | W21: 4.4 | AA21: #N/A
AA22: #N/A
AA23: #N/A
V25: 2 | W25: 1
U26: =A2 -> 20 | V26: {=INDEX(N2:W21,,$Y$2)} -> 1.85 | W26: {=INDEX(B2:K21,,$Y$2)} -> 1.65
U27: =A3 -> 25 | V27: 1.85 | W27: 1.65
U28: =A4 -> 30 | V28: 1.85 | W28: 2.05
U29: =A5 -> 35 | V29: 2.43 | W29: 2.05
U30: =A6 -> 40 | V30: 2.65 | W30: 2.05
U31: =A7 -> 45 | V31: 2.65 | W31: 2.05
U32: =A8 -> 50 | V32: 2.65 | W32: 2.05
U33: =A9 -> 55 | V33: 2.65 | W33: 2.23
U34: =A10 -> 60 | V34: 2.65 | W34: 2.23
U35: =A11 -> 65 | V35: 2.97 | W35: 2.23
U36: =A12 -> 70 | V36: 3.19 | W36: 2.43
U37: =A13 -> 75 | V37: 3.19 | W37: 2.43
U38: =A14 -> 80 | V38: 3.19 | W38: 2.43
... U45: =A21 -> 115 | V45: 3.91 | W45: 3.32
U46: =A22 -> 0 | V46: #N/A
U47: =A23 -> 0 | V47: #N/A

Sheet Лист5
A1: q_rate | B1: 6 | C1: 6.1 | D1: 6.2 | E1: 6.3 | F1: 6.4 | G1: 6.5 | H1: 6.6 | I1: 6.7 | J1: 6.8 | K1: 6.9 | L1: 7 | M1: 7.1 | N1: 7.2 | O1: 7.3 | P1: 7.4 | S1: q_rate | T1: 6 | U1: 6.1 | V1: 6.2 | W1: 6.3 | X1: 6.4 | Y1: 6.5 | Z1: 6.6 | AA1: 6.7 | AB1: 6.8 | AC1: 6.9 | AD1: 7 | AE1: 7.1 | AF1: 7.2 | AG1: 7.3 | AH1: 7.4 | AK1: q_rate | AL1: 6 | AM1: 6.1 | AN1: 6.2 | AO1: 6.3 | AP1: 6.4 | AQ1: 6.5 | AR1: 6.6 | AS1: 6.7 | AT1: 6.8 | AU1: 6.9 | AV1: 7 | AW1: 7.1 | AX1: 7.2 | AY1: 7.3 | AZ1: 7.4 | BC1: q_rate | BD1: 6 | BE1: 6.1 | BF1: 6.2 | BG1: 6.3 | BH1: 6.4 | BI1: 6.5 | BJ1: 6.6 | BK1: 6.7 | BL1: 6.8 | BM1: 6.9 | BN1: 7 | BO1: 7.1 | BP1: 7.2 | BQ1: 7.3 | BR1: 7.4 | BU1: q_rate | BV1: 6 | BW1: 6.1 | BX1: 6.2 | BY1: 6.3 | BZ1: 6.4 | CA1: 6.5 | CB1: 6.6 | CC1: 6.7 | CD1: 6.8 | CE1: 6.9 | CF1: 7 | CG1: 7.1 | CH1: 7.2 | CI1: 7.3 | CJ1: 7.4
A2: 20 | B2: 4.01 | C2: 4.08 | D2: 4.15 | E2: 4.21 | F2: 4.27 | G2: 4.34 | H2: 4.4 | I2: 4.46 | J2: 4.53 | K2: 4.59 | L2: 4.66 | M2: 4.73 | N2: 4.79 | O2: 4.85 | P2: 4.91 | S2: 20 | T2: 3.26 | U2: 3.31 | V2: 3.36 | W2: 3.42 | X2: 3.47 | Y2: 3.52 | Z2: 3.57 | AA2: 3.62 | AB2: 3.68 | AC2: 3.73 | AD2: 3.78 | AE2: 3.83 | AF2: 3.88 | AG2: 3.93 | AH2: 3.98 | AK2: 20 | AL2: 2.54 | AM2: 2.57 | AN2: 2.61 | AO2: 2.65 | AP2: 2.69 | AQ2: 2.73 | AR2: 2.77 | AS2: 2.81 | AT2: 2.85 | AU2: 2.89 | AV2: 2.93 | AW2: 2.97 | AX2: 3.01 | AY2: 3.05 | AZ2: 3.09 | BC2: 20 | BD2: 1.75 | BE2: 1.75 | BF2: 2.11 | BG2: 2.12 | BH2: 2.13 | BI2: 2.14 | BJ2: 2.16 | BK2: 2.18 | BL2: 2.2 | BM2: 2.23 | BN2: 2.31 | BO2: 2.31 | BP2: 2.31 | BQ2: 2.78 | BR2: 2.81 | BU2: 20 | BV2: 1.32 | BW2: 1.32 | BX2: 1.32 | BY2: 1.32 | BZ2: 1.32 | CA2: 1.32 | CB2: 1.32 | CC2: 1.32 | CD2: 1.88 | CE2: 1.88 | CF2: 2.07 | CG2: 2.07 | CH2: 2.07 | CI2: 2.07 | CJ2: 2.08
A3: 25 | B3: 4.01 | C3: 4.08 | D3: 4.15 | E3: 4.21 | F3: 4.27 | G3: 4.34 | H3: 4.4 | I3: 4.46 | J3: 4.53 | K3: 4.59 | L3: 4.66 | M3: 4.73 | N3: 4.79 | O3: 4.85 | P3: 4.91 | S3: 25 | T3: 3.26 | U3: 3.31 | V3: 3.36 | W3: 3.42 | X3: 3.47 | Y3: 3.52 | Z3: 3.57 | AA3: 3.62 | AB3: 3.68 | AC3: 3.73 | AD3: 3.78 | AE3: 3.83 | AF3: 3.88 | AG3: 3.93 | AH3: 3.98 | AK3: 25 | AL3: 2.54 | AM3: 2.57 | AN3: 2.61 | AO3: 2.65 | AP3: 2.69 | AQ3: 2.73 | AR3: 2.77 | AS3: 2.81 | AT3: 2.85 | AU3: 2.89 | AV3: 2.93 | AW3: 2.97 | AX3: 3.01 | AY3: 3.05 | AZ3: 3.09 | BC3: 25 | BD3: 1.75 | BE3: 1.75 | BF3: 2.11 | BG3: 2.12 | BH3: 2.13 | BI3: 2.14 | BJ3: 2.16 | BK3: 2.18 | BL3: 2.2 | BM3: 2.23 | BN3: 2.31 | BO3: 2.31 | BP3: 2.31 | BQ3: 2.78 | BR3: 2.81 | BU3: 25 | BV3: 1.63 | BW3: 1.63 | BX3: 1.63 | BY3: 1.68 | BZ3: 1.68 | CA3: 1.68 | CB3: 1.68 | CC3: 1.68 | CD3: 1.88 | CE3: 1.88 | CF3: 2.07 | CG3: 2.07 | CH3: 2.07 | CI3: 2.07 | CJ3: 2.08
A4: 35 | B4: 4.01 | C4: 4.08 | D4: 4.15 | E4: 4.21 | F4: 4.27 | G4: 4.34 | H4: 4.4 | I4: 4.46 | J4: 4.53 | K4: 4.59 | L4: 4.66 | M4: 4.73 | N4: 4.79 | O4: 4.85 | P4: 4.91 | S4: 30 | T4: 3.26 | U4: 3.31 | V4: 3.36 | W4: 3.42 | X4: 3.47 | Y4: 3.52 | Z4: 3.57 | AA4: 3.62 | AB4: 3.68 | AC4: 3.73 | AD4: 3.78 | AE4: 3.83 | AF4: 3.88 | AG4: 3.93 | AH4: 3.98 | AK4: 30 | AL4: 2.54 | AM4: 2.57 | AN4: 2.61 | AO4: 2.65 | AP4: 2.69 | AQ4: 2.73 | AR4: 2.77 | AS4: 2.81 | AT4: 2.86 | AU4: 2.9 | AV4: 2.93 | AW4: 2.97 | AX4: 3.01 | AY4: 3.05 | AZ4: 3.09 | BC4: 30 | BD4: 2.17 | BE4: 2.18 | BF4: 2.19 | BG4: 2.21 | BH4: 2.23 | BI4: 2.3 | BJ4: 2.62 | BK4: 2.64 | BL4: 2.66 | BM4: 2.68 | BN4: 2.71 | BO4: 2.73 | BP4: 2.76 | BQ4: 2.78 | BR4: 2.81 | BU4: 30 | BV4: 1.81 | BW4: 1.91 | BX4: 1.91 | BY4: 2.07 | BZ4: 2.07 | CA4: 2.07 | CB4: 2.07 | CC4: 2.07 | CD4: 2.07 | CE4: 2.07 | CF4: 2.07 | CG4: 2.07 | CH4: 2.07 | CI4: 2.07 | CJ4: 2.08
A5: 40 | B5: 4.01 | C5: 4.08 | D5: 4.15 | E5: 4.21 | F5: 4.27 | G5: 4.34 | H5: 4.4 | I5: 4.46 | J5: 4.53 | K5: 4.59 | L5: 4.66 | M5: 4.73 | N5: 4.79 | O5: 4.85 | P5: 4.91 | S5: 35 | T5: 3.26 | U5: 3.31 | V5: 3.36 | W5: 3.42 | X5: 3.47 | Y5: 3.52 | Z5: 3.58 | AA5: 3.62 | AB5: 3.68 | AC5: 3.73 | AD5: 3.78 | AE5: 3.83 | AF5: 3.88 | AG5: 3.93 | AH5: 3.98 | AK5: 35 | AL5: 2.54 | AM5: 2.57 | AN5: 2.61 | AO5: 2.65 | AP5: 2.69 | AQ5: 2.73 | AR5: 2.77 | AS5: 2.81 | AT5: 2.86 | AU5: 2.9 | AV5: 2.93 | AW5: 2.97 | AX5: 3.01 | AY5: 3.05 | AZ5: 3.09 | BC5: 35 | BD5: 2.17 | BE5: 2.18 | BF5: 2.19 | BG5: 2.21 | BH5: 2.23 | BI5: 2.3 | BJ5: 2.62 | BK5: 2.64 | BL5: 2.66 | BM5: 2.68 | BN5: 2.71 | BO5: 2.76 | BP5: 2.76 | BQ5: 2.78 | BR5: 2.81 | BU5: 35 | BV5: 1.81 | BW5: 1.91 | BX5: 1.91 | BY5: 2.07 | BZ5: 2.07 | CA5: 2.07 | CB5: 2.07 | CC5: 2.08 | CD5: 2.08 | CE5: 2.08 | CF5: 2.08 | CG5: 2.08 | CH5: 2.08 | CI5: 2.08 | CJ5: 2.08
A6: 45 | B6: 4.01 | C6: 4.08 | D6: 4.15 | E6: 4.21 | F6: 4.27 | G6: 4.34 | H6: 4.4 | I6: 4.46 | J6: 4.53 | K6: 4.59 | L6: 4.66 | M6: 4.73 | N6: 4.79 | O6: 4.85 | P6: 4.91 | S6: 40 | T6: 3.26 | U6: 3.31 | V6: 3.36 | W6: 3.42 | X6: 3.47 | Y6: 3.52 | Z6: 3.58 | AA6: 3.62 | AB6: 3.68 | AC6: 3.74 | AD6: 3.78 | AE6: 3.84 | AF6: 3.88 | AG6: 3.93 | AH6: 3.98 | AK6: 40 | AL6: 2.54 | AM6: 2.57 | AN6: 2.61 | AO6: 2.65 | AP6: 2.69 | AQ6: 2.73 | AR6: 2.77 | AS6: 2.81 | AT6: 2.86 | AU6: 2.9 | AV6: 2.94 | AW6: 2.98 | AX6: 3.01 | AY6: 3.05 | AZ6: 3.09 | BC6: 40 | BD6: 2.22 | BE6: 2.26 | BF6: 2.26 | BG6: 2.28 | BH6: 2.32 | BI6: 2.32 | BJ6: 2.62 | BK6: 2.64 | BL6: 2.66 | BM6: 2.68 | BN6: 2.71 | BO6: 2.76 | BP6: 2.76 | BQ6: 2.78 | BR6: 2.81 | BU6: 40 | BV6: 1.81 | BW6: 1.91 | BX6: 1.91 | BY6: 2.07 | BZ6: 2.07 | CA6: 2.07 | CB6: 2.07 | CC6: 2.08 | CD6: 2.08 | CE6: 2.08 | CF6: 2.08 | CG6: 2.08 | CH6: 2.08 | CI6: 2.08 | CJ6: 2.08
A7: 50 | B7: 4.01 | C7: 4.08 | D7: 4.15 | E7: 4.21 | F7: 4.27 | G7: 4.34 | H7: 4.4 | I7: 4.46 | J7: 4.53 | K7: 4.59 | L7: 4.66 | M7: 4.73 | N7: 4.79 | O7: 4.85 | P7: 4.91 | S7: 45 | T7: 3.27 | U7: 3.33 | V7: 3.37 | W7: 3.42 | X7: 3.47 | Y7: 3.52 | Z7: 3.58 | AA7: 3.62 | AB7: 3.68 | AC7: 3.74 | AD7: 3.78 | AE7: 3.86 | AF7: 3.88 | AG7: 3.93 | AH7: 3.98 | AK7: 45 | AL7: 2.54 | AM7: 2.57 | AN7: 2.61 | AO7: 2.66 | AP7: 2.7 | AQ7: 2.73 | AR7: 2.77 | AS7: 2.81 | AT7: 2.86 | AU7: 2.9 | AV7: 2.94 | AW7: 2.98 | AX7: 3.01 | AY7: 3.05 | AZ7: 3.09 | BC7: 45 | BD7: 2.22 | BE7: 2.26 | BF7: 2.26 | BG7: 2.28 | BH7: 2.32 | BI7: 2.32 | BJ7: 2.62 | BK7: 2.64 | BL7: 2.66 | BM7: 2.68 | BN7: 2.76 | BO7: 2.76 | BP7: 2.76 | BQ7: 3.03 | BR7: 3.03 | BU7: 45 | BV7: 1.81 | BW7: 2.02 | BX7: 2.02 | BY7: 2.07 | BZ7: 2.07 | CA7: 2.07 | CB7: 2.07 | CC7: 2.08 | CD7: 2.08 | CE7: 2.08 | CF7: 2.08 | CG7: 2.08 | CH7: 2.08 | CI7: 2.08 | CJ7: 2.08
A8: 55 | B8: 4.01 | C8: 4.08 | D8: 4.15 | E8: 4.21 | F8: 4.27 | G8: 4.34 | H8: 4.4 | I8: 4.46 | J8: 4.53 | K8: 4.59 | L8: 4.66 | M8: 4.73 | N8: 4.79 | O8: 4.85 | P8: 4.91 | S8: 50 | T8: 3.27 | U8: 3.33 | V8: 3.37 | W8: 3.48 | X8: 3.48 | Y8: 3.52 | Z8: 3.58 | AA8: 3.63 | AB8: 3.69 | AC8: 3.74 | AD8: 3.79 | AE8: 3.86 | AF8: 3.88 | AG8: 3.93 | AH8: 3.98 | AK8: 50 | AL8: 2.54 | AM8: 2.57 | AN8: 2.61 | AO8: 2.66 | AP8: 2.7 | AQ8: 2.73 | AR8: 2.77 | AS8: 2.81 | AT8: 2.86 | AU8: 2.9 | AV8: 2.94 | AW8: 2.98 | AX8: 3.02 | AY8: 3.05 | AZ8: 3.1 | BC8: 50 | BD8: 2.26 | BE8: 2.28 | BF8: 2.36 | BG8: 2.36 | BH8: 2.57 | BI8: 2.59 | BJ8: 2.62 | BK8: 2.64 | BL8: 2.66 | BM8: 2.68 | BN8: 2.76 | BO8: 2.76 | BP8: 2.76 | BQ8: 3.03 | BR8: 3.03 | BU8: 50 | BV8: 1.81 | BW8: 2.02 | BX8: 2.02 | BY8: 2.08 | BZ8: 2.08 | CA8: 2.08 | CB8: 2.08 | CC8: 2.08 | CD8: 2.08 | CE8: 2.08 | CF8: 2.08 | CG8: 2.25 | CH8: 2.25 | CI8: 2.25 | CJ8: 2.25
A9: 60 | B9: 4.01 | C9: 4.08 | D9: 4.15 | E9: 4.21 | F9: 4.27 | G9: 4.34 | H9: 4.4 | I9: 4.46 | J9: 4.53 | K9: 4.59 | L9: 4.66 | M9: 4.73 | N9: 4.79 | O9: 4.85 | P9: 4.91 | S9: 55 | T9: 3.27 | U9: 3.33 | V9: 3.37 | W9: 3.48 | X9: 3.48 | Y9: 3.52 | Z9: 3.58 | AA9: 3.63 | AB9: 3.69 | AC9: 3.74 | AD9: 3.79 | AE9: 3.86 | AF9: 3.9 | AG9: 3.95 | AH9: 4.01 | AK9: 55 | AL9: 2.57 | AM9: 2.57 | AN9: 2.61 | AO9: 2.66 | AP9: 2.7 | AQ9: 2.74 | AR9: 2.78 | AS9: 2.82 | AT9: 2.86 | AU9: 2.9 | AV9: 2.94 | AW9: 2.98 | AX9: 3.02 | AY9: 3.05 | AZ9: 3.1 | BC9: 55 | BD9: 2.26 | BE9: 2.28 | BF9: 2.36 | BG9: 2.36 | BH9: 2.57 | BI9: 2.59 | BJ9: 2.62 | BK9: 2.68 | BL9: 2.68 | BM9: 2.68 | BN9: 2.88 | BO9: 2.95 | BP9: 2.95 | BQ9: 3.03 | BR9: 3.03 | BU9: 55 | BV9: 1.81 | BW9: 2.02 | BX9: 2.02 | BY9: 2.08 | BZ9: 2.08 | CA9: 2.08 | CB9: 2.08 | CC9: 2.08 | CD9: 2.08 | CE9: 2.08 | CF9: 2.08 | CG9: 2.25 | CH9: 2.25 | CI9: 2.25 | CJ9: 2.25
A10: 65 | B10: 4.01 | C10: 4.08 | D10: 4.15 | E10: 4.21 | F10: 4.27 | G10: 4.34 | H10: 4.4 | I10: 4.46 | J10: 4.53 | K10: 4.59 | L10: 4.66 | M10: 4.73 | N10: 4.79 | O10: 4.85 | P10: 4.91 | S10: 60 | T10: 3.27 | U10: 3.33 | V10: 3.37 | W10: 3.48 | X10: 3.48 | Y10: 3.53 | Z10: 3.58 | AA10: 3.63 | AB10: 3.69 | AC10: 3.74 | AD10: 3.79 | AE10: 3.86 | AF10: 3.9 | AG10: 3.95 | AH10: 4.01 | AK10: 60 | AL10: 2.58 | AM10: 2.58 | AN10: 2.62 | AO10: 2.66 | AP10: 2.7 | AQ10: 2.74 | AR10: 2.78 | AS10: 2.82 | AT10: 2.86 | AU10: 2.9 | AV10: 2.94 | AW10: 2.98 | AX10: 3.02 | AY10: 3.06 | AZ10: 3.1 | BC10: 60 | BD10: 2.3 | BE10: 2.32 | BF10: 2.36 | BG10: 2.36 | BH10: 2.57 | BI10: 2.59 | BJ10: 2.62 | BK10: 2.68 | BL10: 2.68 | BM10: 2.68 | BN10: 2.88 | BO10: 2.95 | BP10: 2.95 | BQ10: 3.03 | BR10: 3.03 | BU10: 60 | BV10: 1.81 | BW10: 2.02 | BX10: 2.02 | BY10: 2.08 | BZ10: 2.08 | CA10: 2.08 | CB10: 2.08 | CC10: 2.08 | CD10: 2.08 | CE10: 2.08 | CF10: 2.08 | CG10: 2.25 | CH10: 2.25 | CI10: 2.25 | CJ10: 2.25
A11: 70 | B11: 4.01 | C11: 4.08 | D11: 4.15 | E11: 4.21 | F11: 4.27 | G11: 4.34 | H11: 4.4 | I11: 4.46 | J11: 4.53 | K11: 4.59 | L11: 4.66 | M11: 4.73 | N11: 4.79 | O11: 4.85 | P11: 4.91 | S11: 65 | T11: 3.27 | U11: 3.33 | V11: 3.37 | W11: 3.48 | X11: 3.48 | Y11: 3.53 | Z11: 3.58 | AA11: 3.63 | AB11: 3.69 | AC11: 3.74 | AD11: 3.79 | AE11: 3.86 | AF11: 3.9 | AG11: 3.95 | AH11: 4.01 | AK11: 65 | AL11: 2.58 | AM11: 2.58 | AN11: 2.62 | AO11: 2.66 | AP11: 2.7 | AQ11: 2.74 | AR11: 2.78 | AS11: 2.82 | AT11: 2.86 | AU11: 2.9 | AV11: 2.94 | AW11: 2.98 | AX11: 3.02 | AY11: 3.06 | AZ11: 3.1 | BC11: 65 | BD11: 2.3 | BE11: 2.32 | BF11: 2.36 | BG11: 2.36 | BH11: 2.57 | BI11: 2.59 | BJ11: 2.62 | BK11: 2.81 | BL11: 2.81 | BM11: 2.88 | BN11: 2.88 | BO11: 2.95 | BP11: 2.95 | BQ11: 3.03 | BR11: 3.03 | BU11: 65 | BV11: 1.81 | BW11: 2.02 | BX11: 2.02 | BY11: 2.25 | BZ11: 2.25 | CA11: 2.25 | CB11: 2.25 | CC11: 2.25 | CD11: 2.25 | CE11: 2.25 | CF11: 2.25 | CG11: 2.25 | CH11: 2.25 | CI11: 2.25 | CJ11: 2.25
A12: 75 | B12: 4.01 | C12: 4.08 | D12: 4.15 | E12: 4.21 | F12: 4.27 | G12: 4.34 | H12: 4.4 | I12: 4.46 | J12: 4.53 | K12: 4.59 | L12: 4.66 | M12: 4.73 | N12: 4.79 | O12: 4.85 | P12: 4.91 | S12: 70 | T12: 3.33 | U12: 3.33 | V12: 3.37 | W12: 3.48 | X12: 3.48 | Y12: 3.53 | Z12: 3.58 | AA12: 3.63 | AB12: 3.69 | AC12: 3.81 | AD12: 3.81 | AE12: 3.86 | AF12: 3.9 | AG12: 3.95 | AH12: 4.01 | AK12: 70 | AL12: 2.58 | AM12: 2.58 | AN12: 2.62 | AO12: 2.66 | AP12: 2.7 | AQ12: 2.74 | AR12: 2.78 | AS12: 2.82 | AT12: 2.86 | AU12: 2.9 | AV12: 2.96 | AW12: 2.98 | AX12: 3.03 | AY12: 3.06 | AZ12: 3.1 | BC12: 70 | BD12: 2.32 | BE12: 2.36 | BF12: 2.36 | BG12: 2.55 | BH12: 2.57 | BI12: 2.59 | BJ12: 2.62 | BK12: 2.81 | BL12: 2.81 | BM12: 2.88 | BN12: 2.88 | BO12: 2.95 | BP12: 2.95 | BQ12: 3.12 | BR12: 3.32 | BU12: 70 | BV12: 2.45 | BW12: 2.45 | BX12: 2.45 | BY12: 2.45 | BZ12: 2.45 | CA12: 2.45 | CB12: 2.45 | CC12: 2.45 | CD12: 2.45 | CE12: 2.45 | CF12: 2.45 | CG12: 2.45 | CH12: 2.45 | CI12: 2.45 | CJ12: 2.45
A13: 80 | B13: 4.01 | C13: 4.08 | D13: 4.15 | E13: 4.21 | F13: 4.27 | G13: 4.34 | H13: 4.4 | I13: 4.46 | J13: 4.53 | K13: 4.59 | L13: 4.66 | M13: 4.73 | N13: 4.79 | O13: 4.85 | P13: 4.91 | S13: 75 | T13: 3.35 | U13: 3.35 | V13: 3.37 | W13: 3.48 | X13: 3.48 | Y13: 3.53 | Z13: 3.59 | AA13: 3.63 | AB13: 3.69 | AC13: 3.87 | AD13: 3.87 | AE13: 3.87 | AF13: 3.91 | AG13: 3.96 | AH13: 4.01 | AK13: 75 | AL13: 2.58 | AM13: 2.58 | AN13: 2.62 | AO13: 2.66 | AP13: 2.71 | AQ13: 2.74 | AR13: 2.78 | AS13: 2.82 | AT13: 2.86 | AU13: 2.9 | AV13: 2.96 | AW13: 2.98 | AX13: 3.03 | AY13: 3.06 | AZ13: 3.1 | BC13: 75 | BD13: 2.32 | BE13: 2.36 | BF13: 2.36 | BG13: 2.55 | BH13: 2.57 | BI13: 2.59 | BJ13: 2.62 | BK13: 2.81 | BL13: 2.81 | BM13: 2.88 | BN13: 2.88 | BO13: 2.95 | BP13: 2.95 | BQ13: 3.12 | BR13: 3.32
A14: 85 | B14: 4.01 | C14: 4.08 | D14: 4.15 | E14: 4.21 | F14: 4.27 | G14: 4.34 | H14: 4.4 | I14: 4.46 | J14: 4.53 | K14: 4.59 | L14: 4.66 | M14: 4.73 | N14: 4.79 | O14: 4.85 | P14: 4.91 | S14: 80 | T14: 3.35 | U14: 3.35 | V14: 3.37 | W14: 3.48 | X14: 3.48 | Y14: 3.53 | Z14: 3.63 | AA14: 3.63 | AB14: 3.69 | AC14: 3.87 | AD14: 3.87 | AE14: 3.87 | AF14: 3.91 | AG14: 3.96 | AH14: 4.01 | AK14: 80 | AL14: 2.62 | AM14: 2.62 | AN14: 2.62 | AO14: 2.66 | AP14: 2.71 | AQ14: 2.74 | AR14: 2.78 | AS14: 2.82 | AT14: 2.87 | AU14: 2.9 | AV14: 2.96 | AW14: 2.98 | AX14: 3.03 | AY14: 3.06 | AZ14: 3.1 | BC14: 80 | BD14: 2.49 | BE14: 2.51 | BF14: 2.53 | BG14: 2.55 | BH14: 2.57 | BI14: 2.59 | BJ14: 2.62 | BK14: 2.81 | BL14: 2.81 | BM14: 2.88 | BN14: 2.88 | BO14: 3.07 | BP14: 3.12 | BQ14: 3.12 | BR14: 3.32
A15: 90 | B15: 4.02 | C15: 4.08 | D15: 4.15 | E15: 4.21 | F15: 4.27 | G15: 4.34 | H15: 4.4 | I15: 4.46 | J15: 4.53 | K15: 4.59 | L15: 4.66 | M15: 4.73 | N15: 4.79 | O15: 4.85 | P15: 4.92 | S15: 85 | T15: 3.35 | U15: 3.35 | V15: 3.39 | W15: 3.48 | X15: 3.48 | Y15: 3.53 | Z15: 3.63 | AA15: 3.63 | AB15: 3.69 | AC15: 3.87 | AD15: 3.87 | AE15: 3.87 | AF15: 3.91 | AG15: 3.96 | AH15: 4.01 | AK15: 85 | AL15: 2.62 | AM15: 2.62 | AN15: 2.62 | AO15: 2.66 | AP15: 2.73 | AQ15: 2.74 | AR15: 2.78 | AS15: 2.82 | AT15: 2.87 | AU15: 2.9 | AV15: 2.98 | AW15: 2.98 | AX15: 3.03 | AY15: 3.06 | AZ15: 3.1 | BC15: 85 | BD15: 2.49 | BE15: 2.51 | BF15: 2.53 | BG15: 2.55 | BH15: 2.57 | BI15: 2.59 | BJ15: 2.77 | BK15: 2.81 | BL15: 2.81 | BM15: 2.88 | BN15: 2.88 | BO15: 3.07 | BP15: 3.12 | BQ15: 3.12 | BR15: 3.32
A16: 95 | B16: 4.02 | C16: 4.08 | D16: 4.15 | E16: 4.21 | F16: 4.27 | G16: 4.34 | H16: 4.4 | I16: 4.46 | J16: 4.53 | K16: 4.59 | L16: 4.66 | M16: 4.73 | N16: 4.79 | O16: 4.85 | P16: 4.92 | S16: 90 | T16: 3.35 | U16: 3.35 | V16: 3.39 | W16: 3.48 | X16: 3.48 | Y16: 3.53 | Z16: 3.65 | AA16: 3.65 | AB16: 3.69 | AC16: 3.87 | AD16: 3.87 | AE16: 3.87 | AF16: 3.91 | AG16: 3.96 | AH16: 4.01 | AK16: 90 | AL16: 2.67 | AM16: 2.67 | AN16: 2.67 | AO16: 2.67 | AP16: 2.74 | AQ16: 2.74 | AR16: 2.78 | AS16: 2.82 | AT16: 2.87 | AU16: 2.9 | AV16: 2.99 | AW16: 2.99 | AX16: 3.03 | AY16: 3.06 | AZ16: 3.1 | BC16: 90 | BD16: 2.49 | BE16: 2.51 | BF16: 2.53 | BG16: 2.55 | BH16: 2.57 | BI16: 2.59 | BJ16: 2.77 | BK16: 2.81 | BL16: 2.81 | BM16: 2.98 | BN16: 2.98 | BO16: 3.07 | BP16: 3.12 | BQ16: 3.12 | BR16: 3.32
A17: 100 | B17: 4.02 | C17: 4.08 | D17: 4.15 | E17: 4.21 | F17: 4.27 | G17: 4.34 | H17: 4.4 | I17: 4.46 | J17: 4.53 | K17: 4.59 | L17: 4.66 | M17: 4.73 | N17: 4.79 | O17: 4.85 | P17: 4.92 | S17: 95 | T17: 3.35 | U17: 3.35 | V17: 3.39 | W17: 3.48 | X17: 3.48 | Y17: 3.53 | Z17: 3.65 | AA17: 3.65 | AB17: 3.69 | AC17: 3.87 | AD17: 3.87 | AE17: 3.87 | AF17: 3.91 | AG17: 3.96 | AH17: 4.01 | AK17: 95 | AL17: 2.68 | AM17: 2.76 | AN17: 2.76 | AO17: 2.76 | AP17: 2.76 | AQ17: 2.76 | AR17: 2.83 | AS17: 2.83 | AT17: 2.87 | AU17: 2.9 | AV17: 2.99 | AW17: 2.99 | AX17: 3.03 | AY17: 3.06 | AZ17: 3.1 | BC17: 95 | BD17: 2.49 | BE17: 2.51 | BF17: 2.57 | BG17: 2.57 | BH17: 2.57 | BI17: 2.74 | BJ17: 2.77 | BK17: 2.81 | BL17: 2.81 | BM17: 2.98 | BN17: 2.98 | BO17: 3.18 | BP17: 3.23 | BQ17: 3.23 | BR17: 3.32
A18: 105 | B18: 4.02 | C18: 4.08 | D18: 4.15 | E18: 4.21 | F18: 4.27 | G18: 4.34 | H18: 4.4 | I18: 4.46 | J18: 4.54 | K18: 4.6 | L18: 4.66 | M18: 4.73 | N18: 4.79 | O18: 4.85 | P18: 4.92 | S18: 100 | T18: 3.35 | U18: 3.35 | V18: 3.39 | W18: 3.53 | X18: 3.53 | Y18: 3.53 | Z18: 3.65 | AA18: 3.65 | AB18: 3.69 | AC18: 3.87 | AD18: 3.87 | AE18: 3.87 | AF18: 3.91 | AG18: 3.96 | AH18: 4.01 | AK18: 100 | AL18: 2.99 | AM18: 2.99 | AN18: 2.99 | AO18: 2.99 | AP18: 2.99 | AQ18: 2.99 | AR18: 2.99 | AS18: 2.99 | AT18: 2.99 | AU18: 2.99 | AV18: 2.99 | AW18: 2.99 | AX18: 3.03 | AY18: 3.06 | AZ18: 3.1 | BC18: 100 | BD18: 2.49 | BE18: 2.51 | BF18: 2.57 | BG18: 2.57 | BH18: 2.57 | BI18: 2.77 | BJ18: 2.89 | BK18: 2.91 | BL18: 2.93 | BM18: 2.98 | BN18: 2.98 | BO18: 3.18 | BP18: 3.23 | BQ18: 3.23 | BR18: 3.41
A19: 110 | B19: 4.02 | C19: 4.08 | D19: 4.15 | E19: 4.21 | F19: 4.27 | G19: 4.34 | H19: 4.4 | I19: 4.46 | J19: 4.55 | K19: 4.61 | L19: 4.67 | M19: 4.73 | N19: 4.79 | O19: 4.86 | P19: 4.92 | S19: 105 | T19: 3.39 | U19: 3.39 | V19: 3.39 | W19: 3.53 | X19: 3.53 | Y19: 3.53 | Z19: 3.65 | AA19: 3.65 | AB19: 3.69 | AC19: 3.87 | AD19: 3.87 | AE19: 3.87 | AF19: 4.02 | AG19: 4.02 | AH19: 4.02 | AK19: 105 | AL19: 3.01 | AM19: 3.01 | AN19: 3.01 | AO19: 3.01 | AP19: 3.01 | AQ19: 3.01 | AR19: 3.01 | AS19: 3.01 | AT19: 3.01 | AU19: 3.01 | AV19: 3.01 | AW19: 3.01 | AX19: 3.04 | AY19: 3.08 | AZ19: 3.12 | BC19: 105 | BD19: 2.63 | BE19: 2.69 | BF19: 2.69 | BG19: 2.69 | BH19: 2.71 | BI19: 2.77 | BJ19: 2.89 | BK19: 2.91 | BL19: 2.93 | BM19: 2.98 | BN19: 2.98 | BO19: 3.18 | BP19: 3.23 | BQ19: 3.23 | BR19: 3.41
A20: 115 | B20: 4.03 | C20: 4.09 | D20: 4.15 | E20: 4.22 | F20: 4.28 | G20: 4.34 | H20: 4.4 | I20: 4.46 | J20: 4.55 | K20: 4.62 | L20: 4.68 | M20: 4.74 | N20: 4.8 | O20: 4.86 | P20: 4.92 | S20: 110 | T20: 3.39 | U20: 3.39 | V20: 3.39 | W20: 3.53 | X20: 3.53 | Y20: 3.53 | Z20: 3.69 | AA20: 3.69 | AB20: 3.69 | AC20: 3.87 | AD20: 3.87 | AE20: 3.87 | AF20: 5 | AG20: 5.06 | AH20: 5.11 | AK20: 110 | AL20: 3.16 | AM20: 3.16 | AN20: 3.16 | AO20: 3.16 | AP20: 3.16 | AQ20: 3.16 | AR20: 3.16 | AS20: 3.16 | AT20: 3.76 | AU20: 3.76 | AV20: 3.76 | AW20: 3.76 | AX20: 3.84 | AY20: 3.84 | AZ20: 4.37 | BC20: 110 | BD20: 2.81 | BE20: 2.81 | BF20: 2.81 | BG20: 2.82 | BH20: 2.84 | BI20: 2.86 | BJ20: 2.89 | BK20: 2.91 | BL20: 2.93 | BM20: 2.98 | BN20: 2.98 | BO20: 3.33 | BP20: 3.36 | BQ20: 3.41 | BR20: 3.41
C21: 12 | S21: 115 | T21: 3.69 | U21: 3.69 | V21: 3.69 | W21: 3.69 | X21: 3.69 | Y21: 3.69 | Z21: 3.69 | AA21: 3.69 | AB21: 3.69 | AC21: 3.87 | AD21: 3.87 | AE21: 3.87 | AF21: 5.23 | AG21: 5.23 | AH21: 5.23 | AK21: 115 | AL21: 3.16 | AM21: 3.16 | AN21: 3.16 | AO21: 3.16 | AP21: 3.16 | AQ21: 3.16 | AR21: 3.16 | AS21: 3.16 | AT21: 3.76 | AU21: 3.76 | AV21: 3.76 | AW21: 3.76 | AX21: 3.84 | AY21: 3.84 | AZ21: 4.37 | BC21: 115 | BD21: 3.04 | BE21: 3.04 | BF21: 3.04 | BG21: 3.04 | BH21: 3.04 | BI21: 3.04 | BJ21: 3.04 | BK21: 3.04 | BL21: 3.07 | BM21: 3.11 | BN21: 3.11 | BO21: 3.48 | BP21: 3.51 | BQ21: 3.56 | BR21: 3.56
C22: 76-1.44 | D22: 76 1.7 | E22: 76 2.2 | F22: 76-3.0 | G22: 16-41-2.2+76-3.0
A23: 6 | B23: 20 | C23: {=INDEX(B2:P20,,$C$21)} -> 4.73 | D23: {=INDEX(T2:AH21,,$C$21)} -> 3.83 | E23: {=INDEX(AL2:AZ21,,$C$21)} -> 2.97 | F23: {=INDEX(BD2:BR21,,$C$21)} -> 2.31 | G23: {=INDEX(BV2:CJ12,,$C$21)} -> 2.07 | I23: 20 | J23: =MIN($C23:$G23) -> 2.07
A24: 6.1 | B24: 25 | C24: {=INDEX(B3:P21,,$C$21)} -> 4.73 | D24: {=INDEX(T3:AH22,,$C$21)} -> 3.83 | E24: {=INDEX(AL3:AZ22,,$C$21)} -> 2.97 | F24: {=INDEX(BD3:BR22,,$C$21)} -> 2.31 | G24: {=INDEX(BV3:CJ13,,$C$21)} -> 2.07 | I24: 25 | J24: =MIN($C24:$G24) -> 2.07
A25: 6.2 | B25: 30 | D25: {=INDEX(T4:AH23,,$C$21)} -> 3.83 | E25: {=INDEX(AL4:AZ23,,$C$21)} -> 2.97 | F25: {=INDEX(BD4:BR23,,$C$21)} -> 2.73 | G25: {=INDEX(BV4:CJ14,,$C$21)} -> 2.07 | I25: 30 | J25: =MIN($C25:$G25) -> 2.07
A26: 6.3 | B26: 35 | C26: {=INDEX(B4:P22,,$C$21)} -> 4.73 | D26: {=INDEX(T5:AH24,,$C$21)} -> 3.83 | E26: {=INDEX(AL5:AZ24,,$C$21)} -> 2.97 | F26: {=INDEX(BD5:BR24,,$C$21)} -> 2.76 | G26: {=INDEX(BV5:CJ15,,$C$21)} -> 2.08 | I26: 35 | J26: =MIN($C26:$G26) -> 2.08
A27: 6.4 | B27: 40 | C27: {=INDEX(B5:P23,,$C$21)} -> 4.73 | D27: {=INDEX(T6:AH25,,$C$21)} -> 3.84 | E27: {=INDEX(AL6:AZ25,,$C$21)} -> 2.98 | F27: {=INDEX(BD6:BR25,,$C$21)} -> 2.76 | G27: {=INDEX(BV6:CJ16,,$C$21)} -> 2.08 | I27: 40 | J27: =MIN($C27:$G27) -> 2.08
A28: 6.5 | B28: 45 | C28: {=INDEX(B6:P24,,$C$21)} -> 4.73 | D28: {=INDEX(T7:AH26,,$C$21)} -> 3.86 | E28: {=INDEX(AL7:AZ26,,$C$21)} -> 2.98 | F28: {=INDEX(BD7:BR26,,$C$21)} -> 2.76 | G28: {=INDEX(BV7:CJ17,,$C$21)} -> 2.08 | I28: 45 | J28: =MIN($C28:$G28) -> 2.08
A29: 6.6 | B29: 50 | C29: {=INDEX(B7:P25,,$C$21)} -> 4.73 | D29: {=INDEX(T8:AH27,,$C$21)} -> 3.86 | E29: {=INDEX(AL8:AZ27,,$C$21)} -> 2.98 | F29: {=INDEX(BD8:BR27,,$C$21)} -> 2.76 | G29: {=INDEX(BV8:CJ18,,$C$21)} -> 2.25 | I29: 50 | J29: =MIN($C29:$G29) -> 2.25
A30: 6.7 | B30: 55 | C30: {=INDEX(B8:P26,,$C$21)} -> 4.73 | D30: {=INDEX(T9:AH28,,$C$21)} -> 3.86 | E30: {=INDEX(AL9:AZ28,,$C$21)} -> 2.98 | F30: {=INDEX(BD9:BR28,,$C$21)} -> 2.95 | G30: {=INDEX(BV9:CJ19,,$C$21)} -> 2.25 | I30: 55 | J30: =MIN($C30:$G30) -> 2.25
A31: 6.8 | B31: 60 | C31: {=INDEX(B9:P27,,$C$21)} -> 4.73 | D31: {=INDEX(T10:AH29,,$C$21)} -> 3.86 | E31: {=INDEX(AL10:AZ29,,$C$21)} -> 2.98 | F31: {=INDEX(BD10:BR29,,$C$21)} -> 2.95 | G31: {=INDEX(BV10:CJ20,,$C$21)} -> 2.25 | I31: 60 | J31: =MIN($C31:$G31) -> 2.25
A32: 6.9 | B32: 65 | C32: {=INDEX(B10:P28,,$C$21)} -> 4.73 | D32: {=INDEX(T11:AH30,,$C$21)} -> 3.86 | E32: {=INDEX(AL11:AZ30,,$C$21)} -> 2.98 | F32: {=INDEX(BD11:BR30,,$C$21)} -> 2.95 | G32: {=INDEX(BV11:CJ21,,$C$21)} -> 2.25 | I32: 65 | J32: =MIN($C32:$G32) -> 2.25
A33: 7 | B33: 70 | C33: {=INDEX(B11:P29,,$C$21)} -> 4.73 | D33: {=INDEX(T12:AH31,,$C$21)} -> 3.86 | E33: {=INDEX(AL12:AZ31,,$C$21)} -> 2.98 | F33: {=INDEX(BD12:BR31,,$C$21)} -> 2.95 | G33: {=INDEX(BV12:CJ22,,$C$21)} -> 2.45 | I33: 70 | J33: =MIN($C33:$G33) -> 2.45
A34: 7.1 | B34: 75 | C34: {=INDEX(B12:P30,,$C$21)} -> 4.73 | D34: {=INDEX(T13:AH32,,$C$21)} -> 3.87 | E34: {=INDEX(AL13:AZ32,,$C$21)} -> 2.98 | F34: {=INDEX(BD13:BR32,,$C$21)} -> 2.95 | I34: 75 | J34: =MIN($C34:$G34) -> 2.95
A35: 7.2 | B35: 80 | C35: {=INDEX(B13:P31,,$C$21)} -> 4.73 | D35: {=INDEX(T14:AH33,,$C$21)} -> 3.87 | E35: {=INDEX(AL14:AZ33,,$C$21)} -> 2.98 | F35: {=INDEX(BD14:BR33,,$C$21)} -> 3.07 | I35: 80 | J35: =MIN($C35:$G35) -> 2.98
A36: 7.3 | B36: 85 | C36: {=INDEX(B14:P32,,$C$21)} -> 4.73 | D36: {=INDEX(T15:AH34,,$C$21)} -> 3.87 | E36: {=INDEX(AL15:AZ34,,$C$21)} -> 2.98 | F36: {=INDEX(BD15:BR34,,$C$21)} -> 3.07 | I36: 85 | J36: =MIN($C36:$G36) -> 2.98
